package Reactioncraft.bookcase.common;

import java.util.Random;

import net.minecraft.block.Block;
import net.minecraft.world.World;
import net.minecraft.world.gen.feature.WorldGenerator;

public class WorldGenWizimLibary extends WorldGenerator
{
    protected int[] GetValidSpawnBlocks()
    {
        return new int[] {Block.grass.blockID};
    }

    public boolean LocationIsValidSpawn(World var1, int var2, int var3, int var4)
    {
        int var5 = 0;

        for (int var6 = var1.getBlockId(var2, var3, var4); var6 != 0; var6 = var1.getBlockId(var2, var3 + var5, var4))
        {
            ++var5;
        }

        if (var5 > 3)
        {
            return false;
        }
        else
        {
            var3 += var5 - 1;
            int var7 = var1.getBlockId(var2, var3, var4);
            int var8 = var1.getBlockId(var2, var3 + 1, var4);
            int var9 = var1.getBlockId(var2, var3 - 1, var4);
            int[] var10 = this.GetValidSpawnBlocks();
            int var11 = var10.length;

            for (int var12 = 0; var12 < var11; ++var12)
            {
                int var13 = var10[var12];

                if (var8 != 0)
                {
                    return false;
                }

                if (var7 == var13)
                {
                    return true;
                }

                if (var7 == Block.snow.blockID && var9 == var13)
                {
                    return true;
                }
            }

            return false;
        }
    }

    public boolean generate(World var1, Random var2, int var3, int var4, int var5)
    {
        if (this.LocationIsValidSpawn(var1, var3, var4, var5) && this.LocationIsValidSpawn(var1, var3 + 31, var4, var5) && this.LocationIsValidSpawn(var1, var3 + 31, var4, var5 + 26) && this.LocationIsValidSpawn(var1, var3, var4, var5 + 26))
        {
            var1.setBlock(var3 + 0, var4 + 0, var5 + 0, Block.grass.blockID);
            var1.setBlock(var3 + 0, var4 + 0, var5 + 1, Block.grass.blockID);
            var1.setBlock(var3 + 0, var4 + 0, var5 + 2, Block.grass.blockID);
            var1.setBlock(var3 + 0, var4 + 0, var5 + 3, Block.grass.blockID);
            var1.setBlock(var3 + 0, var4 + 0, var5 + 4, Block.grass.blockID);
            var1.setBlock(var3 + 0, var4 + 0, var5 + 5, Block.grass.blockID);
            var1.setBlock(var3 + 0, var4 + 0, var5 + 6, Block.grass.blockID);
            var1.setBlock(var3 + 0, var4 + 0, var5 + 7, Block.grass.blockID);
            var1.setBlock(var3 + 0, var4 + 0, var5 + 8, Block.grass.blockID);
            var1.setBlock(var3 + 0, var4 + 0, var5 + 9, Block.grass.blockID);
            var1.setBlock(var3 + 0, var4 + 0, var5 + 10, Block.grass.blockID);
            var1.setBlock(var3 + 0, var4 + 0, var5 + 11, Block.grass.blockID);
            var1.setBlock(var3 + 0, var4 + 0, var5 + 12, Block.grass.blockID);
            var1.setBlock(var3 + 0, var4 + 0, var5 + 13, Block.grass.blockID);
            var1.setBlock(var3 + 0, var4 + 0, var5 + 14, Block.grass.blockID);
            var1.setBlock(var3 + 0, var4 + 0, var5 + 15, Block.grass.blockID);
            var1.setBlock(var3 + 0, var4 + 0, var5 + 16, Block.grass.blockID);
            var1.setBlock(var3 + 0, var4 + 0, var5 + 17, Block.grass.blockID);
            var1.setBlock(var3 + 0, var4 + 0, var5 + 18, Block.grass.blockID);
            var1.setBlock(var3 + 0, var4 + 0, var5 + 19, Block.grass.blockID);
            var1.setBlock(var3 + 0, var4 + 0, var5 + 20, Block.grass.blockID);
            var1.setBlock(var3 + 0, var4 + 0, var5 + 21, Block.grass.blockID);
            var1.setBlock(var3 + 0, var4 + 0, var5 + 22, Block.grass.blockID);
            var1.setBlock(var3 + 0, var4 + 0, var5 + 23, Block.grass.blockID);
            var1.setBlock(var3 + 0, var4 + 0, var5 + 24, Block.grass.blockID);
            var1.setBlock(var3 + 0, var4 + 0, var5 + 25, Block.grass.blockID);
            var1.setBlock(var3 + 0, var4 + 0, var5 + 26, Block.grass.blockID);
            var1.setBlock(var3 + 1, var4 + 0, var5 + 0, Block.grass.blockID);
            var1.setBlock(var3 + 1, var4 + 0, var5 + 1, Block.grass.blockID);
            var1.setBlock(var3 + 1, var4 + 0, var5 + 2, Block.grass.blockID);
            var1.setBlock(var3 + 1, var4 + 0, var5 + 3, Block.grass.blockID);
            var1.setBlock(var3 + 1, var4 + 0, var5 + 4, Block.grass.blockID);
            var1.setBlock(var3 + 1, var4 + 0, var5 + 5, Block.grass.blockID);
            var1.setBlock(var3 + 1, var4 + 0, var5 + 6, Block.grass.blockID);
            var1.setBlock(var3 + 1, var4 + 0, var5 + 7, Block.grass.blockID);
            var1.setBlock(var3 + 1, var4 + 0, var5 + 8, Block.grass.blockID);
            var1.setBlock(var3 + 1, var4 + 0, var5 + 9, Block.grass.blockID);
            var1.setBlock(var3 + 1, var4 + 0, var5 + 10, Block.grass.blockID);
            var1.setBlock(var3 + 1, var4 + 0, var5 + 11, Block.grass.blockID);
            var1.setBlock(var3 + 1, var4 + 0, var5 + 12, Block.grass.blockID);
            var1.setBlock(var3 + 1, var4 + 0, var5 + 13, Block.grass.blockID);
            var1.setBlock(var3 + 1, var4 + 0, var5 + 14, Block.grass.blockID);
            var1.setBlock(var3 + 1, var4 + 0, var5 + 15, Block.grass.blockID);
            var1.setBlock(var3 + 1, var4 + 0, var5 + 16, Block.grass.blockID);
            var1.setBlock(var3 + 1, var4 + 0, var5 + 17, Block.grass.blockID);
            var1.setBlock(var3 + 1, var4 + 0, var5 + 18, Block.grass.blockID);
            var1.setBlock(var3 + 1, var4 + 0, var5 + 19, Block.grass.blockID);
            var1.setBlock(var3 + 1, var4 + 0, var5 + 20, Block.grass.blockID);
            var1.setBlock(var3 + 1, var4 + 0, var5 + 21, Block.grass.blockID);
            var1.setBlock(var3 + 1, var4 + 0, var5 + 22, Block.grass.blockID);
            var1.setBlock(var3 + 1, var4 + 0, var5 + 23, Block.grass.blockID);
            var1.setBlock(var3 + 1, var4 + 0, var5 + 24, Block.grass.blockID);
            var1.setBlock(var3 + 1, var4 + 0, var5 + 25, Block.grass.blockID);
            var1.setBlock(var3 + 1, var4 + 0, var5 + 26, Block.grass.blockID);
            var1.setBlock(var3 + 2, var4 + 0, var5 + 0, Block.grass.blockID);
            var1.setBlock(var3 + 2, var4 + 0, var5 + 1, Block.grass.blockID);
            var1.setBlock(var3 + 2, var4 + 0, var5 + 2, Block.grass.blockID);
            var1.setBlock(var3 + 2, var4 + 0, var5 + 3, Block.grass.blockID);
            var1.setBlock(var3 + 2, var4 + 0, var5 + 4, Block.grass.blockID);
            var1.setBlock(var3 + 2, var4 + 0, var5 + 5, Block.grass.blockID);
            var1.setBlock(var3 + 2, var4 + 0, var5 + 6, Block.grass.blockID);
            var1.setBlock(var3 + 2, var4 + 0, var5 + 7, Block.grass.blockID);
            var1.setBlock(var3 + 2, var4 + 0, var5 + 8, Block.grass.blockID);
            var1.setBlock(var3 + 2, var4 + 0, var5 + 9, Block.grass.blockID);
            var1.setBlock(var3 + 2, var4 + 0, var5 + 10, Block.grass.blockID);
            var1.setBlock(var3 + 2, var4 + 0, var5 + 11, Block.grass.blockID);
            var1.setBlock(var3 + 2, var4 + 0, var5 + 12, Block.grass.blockID);
            var1.setBlock(var3 + 2, var4 + 0, var5 + 13, Block.grass.blockID);
            var1.setBlock(var3 + 2, var4 + 0, var5 + 14, Block.grass.blockID);
            var1.setBlock(var3 + 2, var4 + 0, var5 + 15, Block.grass.blockID);
            var1.setBlock(var3 + 2, var4 + 0, var5 + 16, Block.grass.blockID);
            var1.setBlock(var3 + 2, var4 + 0, var5 + 17, Block.grass.blockID);
            var1.setBlock(var3 + 2, var4 + 0, var5 + 18, Block.grass.blockID);
            var1.setBlock(var3 + 2, var4 + 0, var5 + 19, Block.grass.blockID);
            var1.setBlock(var3 + 2, var4 + 0, var5 + 20, Block.grass.blockID);
            var1.setBlock(var3 + 2, var4 + 0, var5 + 21, Block.grass.blockID);
            var1.setBlock(var3 + 2, var4 + 0, var5 + 22, Block.grass.blockID);
            var1.setBlock(var3 + 2, var4 + 0, var5 + 23, Block.grass.blockID);
            var1.setBlock(var3 + 2, var4 + 0, var5 + 24, Block.grass.blockID);
            var1.setBlock(var3 + 2, var4 + 0, var5 + 25, Block.grass.blockID);
            var1.setBlock(var3 + 2, var4 + 0, var5 + 26, Block.grass.blockID);
            var1.setBlock(var3 + 3, var4 + 0, var5 + 0, Block.grass.blockID);
            var1.setBlock(var3 + 3, var4 + 0, var5 + 1, Block.grass.blockID);
            var1.setBlock(var3 + 3, var4 + 0, var5 + 2, Block.grass.blockID);
            var1.setBlock(var3 + 3, var4 + 0, var5 + 3, Block.grass.blockID);
            var1.setBlock(var3 + 3, var4 + 0, var5 + 4, Block.grass.blockID);
            var1.setBlock(var3 + 3, var4 + 0, var5 + 5, Block.grass.blockID);
            var1.setBlock(var3 + 3, var4 + 0, var5 + 6, Block.grass.blockID);
            var1.setBlock(var3 + 3, var4 + 0, var5 + 7, Block.grass.blockID);
            var1.setBlock(var3 + 3, var4 + 0, var5 + 8, Block.grass.blockID);
            var1.setBlock(var3 + 3, var4 + 0, var5 + 9, Block.grass.blockID);
            var1.setBlock(var3 + 3, var4 + 0, var5 + 10, Block.dirt.blockID);
            var1.setBlock(var3 + 3, var4 + 0, var5 + 11, Block.grass.blockID);
            var1.setBlock(var3 + 3, var4 + 0, var5 + 12, Block.grass.blockID);
            var1.setBlock(var3 + 3, var4 + 0, var5 + 13, Block.grass.blockID);
            var1.setBlock(var3 + 3, var4 + 0, var5 + 14, Block.dirt.blockID);
            var1.setBlock(var3 + 3, var4 + 0, var5 + 15, Block.grass.blockID);
            var1.setBlock(var3 + 3, var4 + 0, var5 + 16, Block.grass.blockID);
            var1.setBlock(var3 + 3, var4 + 0, var5 + 17, Block.grass.blockID);
            var1.setBlock(var3 + 3, var4 + 0, var5 + 18, Block.grass.blockID);
            var1.setBlock(var3 + 3, var4 + 0, var5 + 19, Block.grass.blockID);
            var1.setBlock(var3 + 3, var4 + 0, var5 + 20, Block.grass.blockID);
            var1.setBlock(var3 + 3, var4 + 0, var5 + 21, Block.grass.blockID);
            var1.setBlock(var3 + 3, var4 + 0, var5 + 22, Block.grass.blockID);
            var1.setBlock(var3 + 3, var4 + 0, var5 + 23, Block.grass.blockID);
            var1.setBlock(var3 + 3, var4 + 0, var5 + 24, Block.grass.blockID);
            var1.setBlock(var3 + 3, var4 + 0, var5 + 25, Block.grass.blockID);
            var1.setBlock(var3 + 3, var4 + 0, var5 + 26, Block.grass.blockID);
            var1.setBlockAndMetadata(var3 + 3, var4 + 1, var5 + 10, Block.wood.blockID, 1);
            var1.setBlock(var3 + 3, var4 + 1, var5 + 11, Block.stairCompactCobblestone.blockID);
            var1.setBlock(var3 + 3, var4 + 1, var5 + 12, Block.stairCompactCobblestone.blockID);
            var1.setBlock(var3 + 3, var4 + 1, var5 + 13, Block.stairCompactCobblestone.blockID);
            var1.setBlockAndMetadata(var3 + 3, var4 + 1, var5 + 14, Block.wood.blockID, 1);
            var1.setBlockAndMetadata(var3 + 3, var4 + 10, var5 + 5, Block.stoneSingleSlab.blockID, 2);
            var1.setBlock(var3 + 3, var4 + 10, var5 + 6, Block.stairCompactPlanks.blockID);
            var1.setBlock(var3 + 3, var4 + 10, var5 + 7, Block.stairCompactPlanks.blockID);
            var1.setBlock(var3 + 3, var4 + 10, var5 + 8, Block.stairCompactPlanks.blockID);
            var1.setBlock(var3 + 3, var4 + 10, var5 + 9, Block.stairCompactPlanks.blockID);
            var1.setBlock(var3 + 3, var4 + 10, var5 + 15, Block.stairCompactPlanks.blockID);
            var1.setBlock(var3 + 3, var4 + 10, var5 + 16, Block.stairCompactPlanks.blockID);
            var1.setBlock(var3 + 3, var4 + 10, var5 + 17, Block.stairCompactPlanks.blockID);
            var1.setBlock(var3 + 3, var4 + 10, var5 + 18, Block.stairCompactPlanks.blockID);
            var1.setBlockAndMetadata(var3 + 3, var4 + 10, var5 + 19, Block.stoneSingleSlab.blockID, 2);
            var1.setBlock(var3 + 4, var4 + 0, var5 + 0, Block.grass.blockID);
            var1.setBlock(var3 + 4, var4 + 0, var5 + 1, Block.grass.blockID);
            var1.setBlock(var3 + 4, var4 + 0, var5 + 2, Block.grass.blockID);
            var1.setBlock(var3 + 4, var4 + 0, var5 + 3, Block.grass.blockID);
            var1.setBlock(var3 + 4, var4 + 0, var5 + 4, Block.dirt.blockID);
            var1.setBlock(var3 + 4, var4 + 0, var5 + 5, Block.grass.blockID);
            var1.setBlock(var3 + 4, var4 + 0, var5 + 6, Block.dirt.blockID);
            var1.setBlock(var3 + 4, var4 + 0, var5 + 7, Block.grass.blockID);
            var1.setBlock(var3 + 4, var4 + 0, var5 + 8, Block.dirt.blockID);
            var1.setBlock(var3 + 4, var4 + 0, var5 + 9, Block.grass.blockID);
            var1.setBlock(var3 + 4, var4 + 0, var5 + 10, Block.dirt.blockID);
            var1.setBlock(var3 + 4, var4 + 0, var5 + 11, Block.dirt.blockID);
            var1.setBlock(var3 + 4, var4 + 0, var5 + 12, Block.dirt.blockID);
            var1.setBlock(var3 + 4, var4 + 0, var5 + 13, Block.dirt.blockID);
            var1.setBlock(var3 + 4, var4 + 0, var5 + 14, Block.dirt.blockID);
            var1.setBlock(var3 + 4, var4 + 0, var5 + 15, Block.grass.blockID);
            var1.setBlock(var3 + 4, var4 + 0, var5 + 16, Block.dirt.blockID);
            var1.setBlock(var3 + 4, var4 + 0, var5 + 17, Block.grass.blockID);
            var1.setBlock(var3 + 4, var4 + 0, var5 + 18, Block.dirt.blockID);
            var1.setBlock(var3 + 4, var4 + 0, var5 + 19, Block.grass.blockID);
            var1.setBlock(var3 + 4, var4 + 0, var5 + 20, Block.dirt.blockID);
            var1.setBlock(var3 + 4, var4 + 0, var5 + 21, Block.grass.blockID);
            var1.setBlock(var3 + 4, var4 + 0, var5 + 22, Block.grass.blockID);
            var1.setBlock(var3 + 4, var4 + 0, var5 + 23, Block.grass.blockID);
            var1.setBlock(var3 + 4, var4 + 0, var5 + 24, Block.grass.blockID);
            var1.setBlock(var3 + 4, var4 + 0, var5 + 25, Block.grass.blockID);
            var1.setBlock(var3 + 4, var4 + 0, var5 + 26, Block.grass.blockID);
            var1.setBlock(var3 + 4, var4 + 1, var5 + 4, Block.cobblestone.blockID);
            var1.setBlock(var3 + 4, var4 + 1, var5 + 5, Block.stairCompactCobblestone.blockID);
            var1.setBlock(var3 + 4, var4 + 1, var5 + 6, Block.cobblestone.blockID);
            var1.setBlock(var3 + 4, var4 + 1, var5 + 7, Block.stairCompactCobblestone.blockID);
            var1.setBlock(var3 + 4, var4 + 1, var5 + 8, Block.cobblestone.blockID);
            var1.setBlock(var3 + 4, var4 + 1, var5 + 9, Block.stairCompactCobblestone.blockID);
            var1.setBlock(var3 + 4, var4 + 1, var5 + 10, Block.cobblestone.blockID);
            var1.setBlock(var3 + 4, var4 + 1, var5 + 11, Block.cobblestone.blockID);
            var1.setBlock(var3 + 4, var4 + 1, var5 + 12, Block.cobblestone.blockID);
            var1.setBlock(var3 + 4, var4 + 1, var5 + 13, Block.cobblestone.blockID);
            var1.setBlock(var3 + 4, var4 + 1, var5 + 14, Block.cobblestone.blockID);
            var1.setBlock(var3 + 4, var4 + 1, var5 + 15, Block.stairCompactCobblestone.blockID);
            var1.setBlock(var3 + 4, var4 + 1, var5 + 16, Block.cobblestone.blockID);
            var1.setBlock(var3 + 4, var4 + 1, var5 + 17, Block.stairCompactCobblestone.blockID);
            var1.setBlock(var3 + 4, var4 + 1, var5 + 18, Block.cobblestone.blockID);
            var1.setBlock(var3 + 4, var4 + 1, var5 + 19, Block.stairCompactCobblestone.blockID);
            var1.setBlock(var3 + 4, var4 + 1, var5 + 20, Block.cobblestone.blockID);
            var1.setBlock(var3 + 4, var4 + 2, var5 + 5, Block.cobblestone.blockID);
            var1.setBlock(var3 + 4, var4 + 2, var5 + 7, Block.cobblestone.blockID);
            var1.setBlock(var3 + 4, var4 + 2, var5 + 9, Block.cobblestone.blockID);
            var1.setBlockAndMetadata(var3 + 4, var4 + 2, var5 + 10, Block.wood.blockID, 1);
            var1.setBlock(var3 + 4, var4 + 2, var5 + 11, Block.stairCompactCobblestone.blockID);
            var1.setBlock(var3 + 4, var4 + 2, var5 + 12, Block.stairCompactCobblestone.blockID);
            var1.setBlock(var3 + 4, var4 + 2, var5 + 13, Block.stairCompactCobblestone.blockID);
            var1.setBlockAndMetadata(var3 + 4, var4 + 2, var5 + 14, Block.wood.blockID, 1);
            var1.setBlock(var3 + 4, var4 + 2, var5 + 15, Block.cobblestone.blockID);
            var1.setBlock(var3 + 4, var4 + 2, var5 + 17, Block.cobblestone.blockID);
            var1.setBlock(var3 + 4, var4 + 2, var5 + 19, Block.cobblestone.blockID);
            var1.setBlockAndMetadata(var3 + 4, var4 + 3, var5 + 5, Block.stoneSingleSlab.blockID, 3);
            var1.setBlockAndMetadata(var3 + 4, var4 + 3, var5 + 6, Block.stoneSingleSlab.blockID, 3);
            var1.setBlockAndMetadata(var3 + 4, var4 + 3, var5 + 7, Block.stoneSingleSlab.blockID, 3);
            var1.setBlockAndMetadata(var3 + 4, var4 + 3, var5 + 8, Block.stoneSingleSlab.blockID, 3);
            var1.setBlockAndMetadata(var3 + 4, var4 + 3, var5 + 9, Block.stoneSingleSlab.blockID, 3);
            var1.setBlockAndMetadata(var3 + 4, var4 + 3, var5 + 10, Block.wood.blockID, 1);
            var1.setBlockAndMetadata(var3 + 4, var4 + 3, var5 + 14, Block.wood.blockID, 1);
            var1.setBlockAndMetadata(var3 + 4, var4 + 3, var5 + 15, Block.stoneSingleSlab.blockID, 3);
            var1.setBlockAndMetadata(var3 + 4, var4 + 3, var5 + 16, Block.stoneSingleSlab.blockID, 3);
            var1.setBlockAndMetadata(var3 + 4, var4 + 3, var5 + 17, Block.stoneSingleSlab.blockID, 3);
            var1.setBlockAndMetadata(var3 + 4, var4 + 3, var5 + 18, Block.stoneSingleSlab.blockID, 3);
            var1.setBlockAndMetadata(var3 + 4, var4 + 3, var5 + 19, Block.stoneSingleSlab.blockID, 3);
            var1.setBlockAndMetadata(var3 + 4, var4 + 6, var5 + 5, Block.stairCompactCobblestone.blockID, 4);
            var1.setBlockAndMetadata(var3 + 4, var4 + 6, var5 + 6, Block.stoneSingleSlab.blockID, 10);
            var1.setBlockAndMetadata(var3 + 4, var4 + 6, var5 + 7, Block.stoneSingleSlab.blockID, 10);
            var1.setBlockAndMetadata(var3 + 4, var4 + 6, var5 + 8, Block.stoneSingleSlab.blockID, 10);
            var1.setBlockAndMetadata(var3 + 4, var4 + 6, var5 + 9, Block.stoneSingleSlab.blockID, 10);
            var1.setBlockAndMetadata(var3 + 4, var4 + 6, var5 + 15, Block.stoneSingleSlab.blockID, 10);
            var1.setBlockAndMetadata(var3 + 4, var4 + 6, var5 + 16, Block.stoneSingleSlab.blockID, 10);
            var1.setBlockAndMetadata(var3 + 4, var4 + 6, var5 + 17, Block.stoneSingleSlab.blockID, 10);
            var1.setBlockAndMetadata(var3 + 4, var4 + 6, var5 + 18, Block.stoneSingleSlab.blockID, 10);
            var1.setBlock(var3 + 4, var4 + 7, var5 + 5, Block.stairCompactCobblestone.blockID);
            var1.setBlockAndMetadata(var3 + 4, var4 + 7, var5 + 6, Block.wood.blockID, 1);
            var1.setBlockAndMetadata(var3 + 4, var4 + 7, var5 + 7, Block.wood.blockID, 1);
            var1.setBlockAndMetadata(var3 + 4, var4 + 7, var5 + 8, Block.wood.blockID, 1);
            var1.setBlockAndMetadata(var3 + 4, var4 + 7, var5 + 9, Block.wood.blockID, 1);
            var1.setBlockAndMetadata(var3 + 4, var4 + 7, var5 + 10, Block.stairCompactCobblestone.blockID, 4);
            var1.setBlockAndMetadata(var3 + 4, var4 + 7, var5 + 11, Block.stoneSingleSlab.blockID, 10);
            var1.setBlockAndMetadata(var3 + 4, var4 + 7, var5 + 12, Block.stoneSingleSlab.blockID, 10);
            var1.setBlockAndMetadata(var3 + 4, var4 + 7, var5 + 13, Block.stoneSingleSlab.blockID, 10);
            var1.setBlockAndMetadata(var3 + 4, var4 + 7, var5 + 14, Block.stairCompactCobblestone.blockID, 4);
            var1.setBlockAndMetadata(var3 + 4, var4 + 7, var5 + 15, Block.wood.blockID, 1);
            var1.setBlockAndMetadata(var3 + 4, var4 + 7, var5 + 16, Block.wood.blockID, 1);
            var1.setBlockAndMetadata(var3 + 4, var4 + 7, var5 + 17, Block.wood.blockID, 1);
            var1.setBlockAndMetadata(var3 + 4, var4 + 7, var5 + 18, Block.wood.blockID, 1);
            var1.setBlockAndMetadata(var3 + 4, var4 + 7, var5 + 19, Block.stairCompactCobblestone.blockID, 4);
            var1.setBlockAndMetadata(var3 + 4, var4 + 8, var5 + 6, Block.wood.blockID, 1);
            var1.setBlock(var3 + 4, var4 + 8, var5 + 7, Block.cloth.blockID);
            var1.setBlock(var3 + 4, var4 + 8, var5 + 8, Block.cloth.blockID);
            var1.setBlockAndMetadata(var3 + 4, var4 + 8, var5 + 9, Block.wood.blockID, 1);
            var1.setBlock(var3 + 4, var4 + 8, var5 + 10, Block.stairCompactCobblestone.blockID);
            var1.setBlock(var3 + 4, var4 + 8, var5 + 14, Block.stairCompactCobblestone.blockID);
            var1.setBlockAndMetadata(var3 + 4, var4 + 8, var5 + 15, Block.wood.blockID, 1);
            var1.setBlock(var3 + 4, var4 + 8, var5 + 16, Block.cloth.blockID);
            var1.setBlock(var3 + 4, var4 + 8, var5 + 17, Block.cloth.blockID);
            var1.setBlockAndMetadata(var3 + 4, var4 + 8, var5 + 18, Block.wood.blockID, 1);
            var1.setBlock(var3 + 4, var4 + 8, var5 + 19, Block.stairCompactCobblestone.blockID);
            var1.setBlockAndMetadata(var3 + 4, var4 + 9, var5 + 6, Block.wood.blockID, 1);
            var1.setBlock(var3 + 4, var4 + 9, var5 + 7, Block.cloth.blockID);
            var1.setBlock(var3 + 4, var4 + 9, var5 + 8, Block.cloth.blockID);
            var1.setBlockAndMetadata(var3 + 4, var4 + 9, var5 + 9, Block.wood.blockID, 1);
            var1.setBlockAndMetadata(var3 + 4, var4 + 9, var5 + 10, Block.wood.blockID, 1);
            var1.setBlockAndMetadata(var3 + 4, var4 + 9, var5 + 14, Block.wood.blockID, 1);
            var1.setBlockAndMetadata(var3 + 4, var4 + 9, var5 + 15, Block.wood.blockID, 1);
            var1.setBlock(var3 + 4, var4 + 9, var5 + 16, Block.cloth.blockID);
            var1.setBlock(var3 + 4, var4 + 9, var5 + 17, Block.cloth.blockID);
            var1.setBlockAndMetadata(var3 + 4, var4 + 9, var5 + 18, Block.wood.blockID, 1);
            var1.setBlockAndMetadata(var3 + 4, var4 + 10, var5 + 4, Block.stoneSingleSlab.blockID, 2);
            var1.setBlockAndMetadata(var3 + 4, var4 + 10, var5 + 5, Block.stoneDoubleSlab.blockID, 2);
            var1.setBlockAndMetadata(var3 + 4, var4 + 10, var5 + 6, Block.wood.blockID, 1);
            var1.setBlockAndMetadata(var3 + 4, var4 + 10, var5 + 7, Block.wood.blockID, 1);
            var1.setBlockAndMetadata(var3 + 4, var4 + 10, var5 + 8, Block.wood.blockID, 1);
            var1.setBlockAndMetadata(var3 + 4, var4 + 10, var5 + 9, Block.wood.blockID, 1);
            var1.setBlock(var3 + 4, var4 + 10, var5 + 10, Block.stairCompactPlanks.blockID);
            var1.setBlock(var3 + 4, var4 + 10, var5 + 11, Block.stairCompactPlanks.blockID);
            var1.setBlock(var3 + 4, var4 + 10, var5 + 12, Block.stairCompactPlanks.blockID);
            var1.setBlock(var3 + 4, var4 + 10, var5 + 13, Block.stairCompactPlanks.blockID);
            var1.setBlock(var3 + 4, var4 + 10, var5 + 14, Block.stairCompactPlanks.blockID);
            var1.setBlockAndMetadata(var3 + 4, var4 + 10, var5 + 15, Block.wood.blockID, 1);
            var1.setBlockAndMetadata(var3 + 4, var4 + 10, var5 + 16, Block.wood.blockID, 1);
            var1.setBlockAndMetadata(var3 + 4, var4 + 10, var5 + 17, Block.wood.blockID, 1);
            var1.setBlockAndMetadata(var3 + 4, var4 + 10, var5 + 18, Block.wood.blockID, 1);
            var1.setBlockAndMetadata(var3 + 4, var4 + 10, var5 + 19, Block.stoneDoubleSlab.blockID, 2);
            var1.setBlockAndMetadata(var3 + 4, var4 + 10, var5 + 20, Block.stoneSingleSlab.blockID, 2);
            var1.setBlock(var3 + 4, var4 + 11, var5 + 6, Block.stairCompactPlanks.blockID);
            var1.setBlock(var3 + 4, var4 + 11, var5 + 7, Block.stairCompactPlanks.blockID);
            var1.setBlock(var3 + 4, var4 + 11, var5 + 8, Block.stairCompactPlanks.blockID);
            var1.setBlock(var3 + 4, var4 + 11, var5 + 9, Block.stairCompactPlanks.blockID);
            var1.setBlock(var3 + 4, var4 + 11, var5 + 15, Block.stairCompactPlanks.blockID);
            var1.setBlock(var3 + 4, var4 + 11, var5 + 16, Block.stairCompactPlanks.blockID);
            var1.setBlock(var3 + 4, var4 + 11, var5 + 17, Block.stairCompactPlanks.blockID);
            var1.setBlock(var3 + 4, var4 + 11, var5 + 18, Block.stairCompactPlanks.blockID);
            var1.setBlock(var3 + 5, var4 + 0, var5 + 0, Block.grass.blockID);
            var1.setBlock(var3 + 5, var4 + 0, var5 + 1, Block.grass.blockID);
            var1.setBlock(var3 + 5, var4 + 0, var5 + 2, Block.grass.blockID);
            var1.setBlock(var3 + 5, var4 + 0, var5 + 3, Block.grass.blockID);
            var1.setBlock(var3 + 5, var4 + 0, var5 + 4, Block.grass.blockID);
            var1.setBlock(var3 + 5, var4 + 0, var5 + 5, Block.dirt.blockID);
            var1.setBlock(var3 + 5, var4 + 0, var5 + 6, Block.dirt.blockID);
            var1.setBlock(var3 + 5, var4 + 0, var5 + 7, Block.dirt.blockID);
            var1.setBlock(var3 + 5, var4 + 0, var5 + 8, Block.dirt.blockID);
            var1.setBlock(var3 + 5, var4 + 0, var5 + 9, Block.dirt.blockID);
            var1.setBlock(var3 + 5, var4 + 0, var5 + 10, Block.dirt.blockID);
            var1.setBlock(var3 + 5, var4 + 0, var5 + 11, Block.dirt.blockID);
            var1.setBlock(var3 + 5, var4 + 0, var5 + 12, Block.dirt.blockID);
            var1.setBlock(var3 + 5, var4 + 0, var5 + 13, Block.dirt.blockID);
            var1.setBlock(var3 + 5, var4 + 0, var5 + 14, Block.dirt.blockID);
            var1.setBlock(var3 + 5, var4 + 0, var5 + 15, Block.dirt.blockID);
            var1.setBlock(var3 + 5, var4 + 0, var5 + 16, Block.dirt.blockID);
            var1.setBlock(var3 + 5, var4 + 0, var5 + 17, Block.dirt.blockID);
            var1.setBlock(var3 + 5, var4 + 0, var5 + 18, Block.dirt.blockID);
            var1.setBlock(var3 + 5, var4 + 0, var5 + 19, Block.dirt.blockID);
            var1.setBlock(var3 + 5, var4 + 0, var5 + 20, Block.grass.blockID);
            var1.setBlock(var3 + 5, var4 + 0, var5 + 21, Block.grass.blockID);
            var1.setBlock(var3 + 5, var4 + 0, var5 + 22, Block.grass.blockID);
            var1.setBlock(var3 + 5, var4 + 0, var5 + 23, Block.grass.blockID);
            var1.setBlock(var3 + 5, var4 + 0, var5 + 24, Block.grass.blockID);
            var1.setBlock(var3 + 5, var4 + 0, var5 + 25, Block.grass.blockID);
            var1.setBlock(var3 + 5, var4 + 0, var5 + 26, Block.grass.blockID);
            var1.setBlockAndMetadata(var3 + 5, var4 + 1, var5 + 4, Block.stairCompactCobblestone.blockID, 2);
            var1.setBlock(var3 + 5, var4 + 1, var5 + 5, Block.cobblestone.blockID);
            var1.setBlock(var3 + 5, var4 + 1, var5 + 6, Block.cobblestone.blockID);
            var1.setBlock(var3 + 5, var4 + 1, var5 + 7, Block.cobblestone.blockID);
            var1.setBlock(var3 + 5, var4 + 1, var5 + 8, Block.cobblestone.blockID);
            var1.setBlock(var3 + 5, var4 + 1, var5 + 9, Block.cobblestone.blockID);
            var1.setBlock(var3 + 5, var4 + 1, var5 + 10, Block.cobblestone.blockID);
            var1.setBlock(var3 + 5, var4 + 1, var5 + 11, Block.cobblestone.blockID);
            var1.setBlock(var3 + 5, var4 + 1, var5 + 12, Block.cobblestone.blockID);
            var1.setBlock(var3 + 5, var4 + 1, var5 + 13, Block.cobblestone.blockID);
            var1.setBlock(var3 + 5, var4 + 1, var5 + 14, Block.cobblestone.blockID);
            var1.setBlock(var3 + 5, var4 + 1, var5 + 15, Block.cobblestone.blockID);
            var1.setBlock(var3 + 5, var4 + 1, var5 + 16, Block.cobblestone.blockID);
            var1.setBlock(var3 + 5, var4 + 1, var5 + 17, Block.cobblestone.blockID);
            var1.setBlock(var3 + 5, var4 + 1, var5 + 18, Block.cobblestone.blockID);
            var1.setBlock(var3 + 5, var4 + 1, var5 + 19, Block.cobblestone.blockID);
            var1.setBlockAndMetadata(var3 + 5, var4 + 1, var5 + 20, Block.stairCompactCobblestone.blockID, 3);
            var1.setBlock(var3 + 5, var4 + 2, var5 + 4, Block.cobblestone.blockID);
            var1.setBlock(var3 + 5, var4 + 2, var5 + 5, Block.cobblestone.blockID);
            var1.setBlock(var3 + 5, var4 + 2, var5 + 6, Block.cobblestone.blockID);
            var1.setBlock(var3 + 5, var4 + 2, var5 + 7, Block.cobblestone.blockID);
            var1.setBlock(var3 + 5, var4 + 2, var5 + 8, Block.cobblestone.blockID);
            var1.setBlock(var3 + 5, var4 + 2, var5 + 9, Block.cobblestone.blockID);
            var1.setBlock(var3 + 5, var4 + 2, var5 + 10, Block.cobblestone.blockID);
            var1.setBlock(var3 + 5, var4 + 2, var5 + 11, Block.cobblestone.blockID);
            var1.setBlock(var3 + 5, var4 + 2, var5 + 12, Block.cobblestone.blockID);
            var1.setBlock(var3 + 5, var4 + 2, var5 + 13, Block.cobblestone.blockID);
            var1.setBlock(var3 + 5, var4 + 2, var5 + 14, Block.cobblestone.blockID);
            var1.setBlock(var3 + 5, var4 + 2, var5 + 15, Block.cobblestone.blockID);
            var1.setBlock(var3 + 5, var4 + 2, var5 + 16, Block.cobblestone.blockID);
            var1.setBlock(var3 + 5, var4 + 2, var5 + 17, Block.cobblestone.blockID);
            var1.setBlock(var3 + 5, var4 + 2, var5 + 18, Block.cobblestone.blockID);
            var1.setBlock(var3 + 5, var4 + 2, var5 + 19, Block.cobblestone.blockID);
            var1.setBlock(var3 + 5, var4 + 2, var5 + 20, Block.cobblestone.blockID);
            var1.setBlockAndMetadata(var3 + 5, var4 + 3, var5 + 4, Block.stoneSingleSlab.blockID, 3);
            var1.setBlockAndMetadata(var3 + 5, var4 + 3, var5 + 5, Block.wood.blockID, 1);
            var1.setBlockAndMetadata(var3 + 5, var4 + 3, var5 + 6, Block.wood.blockID, 1);
            var1.setBlockAndMetadata(var3 + 5, var4 + 3, var5 + 7, Block.wood.blockID, 1);
            var1.setBlockAndMetadata(var3 + 5, var4 + 3, var5 + 8, Block.wood.blockID, 1);
            var1.setBlockAndMetadata(var3 + 5, var4 + 3, var5 + 9, Block.wood.blockID, 1);
            var1.setBlockAndMetadata(var3 + 5, var4 + 3, var5 + 10, Block.wood.blockID, 1);
            var1.setBlock(var3 + 5, var4 + 3, var5 + 11, Block.stairCompactCobblestone.blockID);
            var1.setBlock(var3 + 5, var4 + 3, var5 + 12, Block.stairCompactCobblestone.blockID);
            var1.setBlock(var3 + 5, var4 + 3, var5 + 13, Block.stairCompactCobblestone.blockID);
            var1.setBlockAndMetadata(var3 + 5, var4 + 3, var5 + 14, Block.wood.blockID, 1);
            var1.setBlockAndMetadata(var3 + 5, var4 + 3, var5 + 15, Block.wood.blockID, 1);
            var1.setBlockAndMetadata(var3 + 5, var4 + 3, var5 + 16, Block.wood.blockID, 1);
            var1.setBlockAndMetadata(var3 + 5, var4 + 3, var5 + 17, Block.wood.blockID, 1);
            var1.setBlockAndMetadata(var3 + 5, var4 + 3, var5 + 18, Block.wood.blockID, 1);
            var1.setBlockAndMetadata(var3 + 5, var4 + 3, var5 + 19, Block.wood.blockID, 1);
            var1.setBlockAndMetadata(var3 + 5, var4 + 3, var5 + 20, Block.stoneSingleSlab.blockID, 3);
            var1.setBlockAndMetadata(var3 + 5, var4 + 4, var5 + 5, Block.wood.blockID, 1);
            var1.setBlockAndMetadata(var3 + 5, var4 + 4, var5 + 6, Block.wood.blockID, 1);
            var1.setBlockAndMetadata(var3 + 5, var4 + 4, var5 + 7, Block.wood.blockID, 1);
            var1.setBlockAndMetadata(var3 + 5, var4 + 4, var5 + 8, Block.wood.blockID, 1);
            var1.setBlockAndMetadata(var3 + 5, var4 + 4, var5 + 9, Block.wood.blockID, 1);
            var1.setBlockAndMetadata(var3 + 5, var4 + 4, var5 + 10, Block.wood.blockID, 1);
            var1.setBlockAndMetadata(var3 + 5, var4 + 4, var5 + 14, Block.wood.blockID, 1);
            var1.setBlockAndMetadata(var3 + 5, var4 + 4, var5 + 15, Block.wood.blockID, 1);
            var1.setBlockAndMetadata(var3 + 5, var4 + 4, var5 + 16, Block.wood.blockID, 1);
            var1.setBlockAndMetadata(var3 + 5, var4 + 4, var5 + 17, Block.wood.blockID, 1);
            var1.setBlockAndMetadata(var3 + 5, var4 + 4, var5 + 18, Block.wood.blockID, 1);
            var1.setBlockAndMetadata(var3 + 5, var4 + 4, var5 + 19, Block.wood.blockID, 1);
            var1.setBlockAndMetadata(var3 + 5, var4 + 5, var5 + 5, Block.wood.blockID, 1);
            var1.setBlockAndMetadata(var3 + 5, var4 + 5, var5 + 6, Block.planks.blockID, 2);
            var1.setBlock(var3 + 5, var4 + 5, var5 + 7, Block.thinGlass.blockID);
            var1.setBlock(var3 + 5, var4 + 5, var5 + 8, Block.thinGlass.blockID);
            var1.setBlockAndMetadata(var3 + 5, var4 + 5, var5 + 9, Block.planks.blockID, 2);
            var1.setBlockAndMetadata(var3 + 5, var4 + 5, var5 + 10, Block.wood.blockID, 1);
            var1.setBlockAndMetadata(var3 + 5, var4 + 5, var5 + 14, Block.wood.blockID, 1);
            var1.setBlockAndMetadata(var3 + 5, var4 + 5, var5 + 15, Block.planks.blockID, 2);
            var1.setBlock(var3 + 5, var4 + 5, var5 + 16, Block.thinGlass.blockID);
            var1.setBlock(var3 + 5, var4 + 5, var5 + 17, Block.thinGlass.blockID);
            var1.setBlockAndMetadata(var3 + 5, var4 + 5, var5 + 18, Block.planks.blockID, 2);
            var1.setBlockAndMetadata(var3 + 5, var4 + 5, var5 + 19, Block.wood.blockID, 1);
            var1.setBlockAndMetadata(var3 + 5, var4 + 6, var5 + 4, Block.stairCompactCobblestone.blockID, 6);
            var1.setBlockAndMetadata(var3 + 5, var4 + 6, var5 + 5, Block.wood.blockID, 1);
            var1.setBlockAndMetadata(var3 + 5, var4 + 6, var5 + 6, Block.planks.blockID, 2);
            var1.setBlock(var3 + 5, var4 + 6, var5 + 7, Block.thinGlass.blockID);
            var1.setBlock(var3 + 5, var4 + 6, var5 + 8, Block.thinGlass.blockID);
            var1.setBlockAndMetadata(var3 + 5, var4 + 6, var5 + 9, Block.planks.blockID, 2);
            var1.setBlockAndMetadata(var3 + 5, var4 + 6, var5 + 10, Block.wood.blockID, 1);
            var1.setBlockAndMetadata(var3 + 5, var4 + 6, var5 + 14, Block.wood.blockID, 1);
            var1.setBlockAndMetadata(var3 + 5, var4 + 6, var5 + 15, Block.planks.blockID, 2);
            var1.setBlock(var3 + 5, var4 + 6, var5 + 16, Block.thinGlass.blockID);
            var1.setBlock(var3 + 5, var4 + 6, var5 + 17, Block.thinGlass.blockID);
            var1.setBlockAndMetadata(var3 + 5, var4 + 6, var5 + 18, Block.planks.blockID, 2);
            var1.setBlockAndMetadata(var3 + 5, var4 + 6, var5 + 19, Block.wood.blockID, 1);
            var1.setBlockAndMetadata(var3 + 5, var4 + 7, var5 + 4, Block.stairCompactCobblestone.blockID, 2);
            var1.setBlockAndMetadata(var3 + 5, var4 + 7, var5 + 5, Block.wood.blockID, 1);
            var1.setBlockAndMetadata(var3 + 5, var4 + 7, var5 + 6, Block.planks.blockID, 2);
            var1.setBlockAndMetadata(var3 + 5, var4 + 7, var5 + 7, Block.planks.blockID, 2);
            var1.setBlockAndMetadata(var3 + 5, var4 + 7, var5 + 8, Block.planks.blockID, 2);
            var1.setBlockAndMetadata(var3 + 5, var4 + 7, var5 + 9, Block.planks.blockID, 2);
            var1.setBlockAndMetadata(var3 + 5, var4 + 7, var5 + 10, Block.wood.blockID, 1);
            var1.setBlockAndMetadata(var3 + 5, var4 + 7, var5 + 11, Block.wood.blockID, 1);
            var1.setBlockAndMetadata(var3 + 5, var4 + 7, var5 + 12, Block.wood.blockID, 1);
            var1.setBlockAndMetadata(var3 + 5, var4 + 7, var5 + 13, Block.wood.blockID, 1);
            var1.setBlockAndMetadata(var3 + 5, var4 + 7, var5 + 14, Block.wood.blockID, 1);
            var1.setBlockAndMetadata(var3 + 5, var4 + 7, var5 + 15, Block.planks.blockID, 2);
            var1.setBlockAndMetadata(var3 + 5, var4 + 7, var5 + 16, Block.planks.blockID, 2);
            var1.setBlockAndMetadata(var3 + 5, var4 + 7, var5 + 17, Block.planks.blockID, 2);
            var1.setBlockAndMetadata(var3 + 5, var4 + 7, var5 + 18, Block.planks.blockID, 2);
            var1.setBlockAndMetadata(var3 + 5, var4 + 7, var5 + 19, Block.wood.blockID, 1);
            var1.setBlockAndMetadata(var3 + 5, var4 + 7, var5 + 20, Block.stairCompactCobblestone.blockID, 7);
            var1.setBlockAndMetadata(var3 + 5, var4 + 8, var5 + 5, Block.wood.blockID, 1);
            var1.setBlock(var3 + 5, var4 + 8, var5 + 6, Block.bookShelf.blockID);
            var1.setBlock(var3 + 5, var4 + 8, var5 + 7, Block.bookShelf.blockID);
            var1.setBlock(var3 + 5, var4 + 8, var5 + 8, Block.bookShelf.blockID);
            var1.setBlock(var3 + 5, var4 + 8, var5 + 9, Block.bookShelf.blockID);
            var1.setBlockAndMetadata(var3 + 5, var4 + 8, var5 + 10, Block.wood.blockID, 1);
            var1.setBlock(var3 + 5, var4 + 8, var5 + 11, Block.cloth.blockID);
            var1.setBlock(var3 + 5, var4 + 8, var5 + 12, Block.cloth.blockID);
            var1.setBlock(var3 + 5, var4 + 8, var5 + 13, Block.cloth.blockID);
            var1.setBlockAndMetadata(var3 + 5, var4 + 8, var5 + 14, Block.wood.blockID, 1);
            var1.setBlock(var3 + 5, var4 + 8, var5 + 15, Block.bookShelf.blockID);
            var1.setBlock(var3 + 5, var4 + 8, var5 + 16, Block.bookShelf.blockID);
            var1.setBlock(var3 + 5, var4 + 8, var5 + 17, Block.bookShelf.blockID);
            var1.setBlock(var3 + 5, var4 + 8, var5 + 18, Block.bookShelf.blockID);
            var1.setBlockAndMetadata(var3 + 5, var4 + 8, var5 + 19, Block.wood.blockID, 1);
            var1.setBlockAndMetadata(var3 + 5, var4 + 8, var5 + 20, Block.stairCompactCobblestone.blockID, 3);
            var1.setBlockAndMetadata(var3 + 5, var4 + 9, var5 + 5, Block.wood.blockID, 1);
            var1.setBlock(var3 + 5, var4 + 9, var5 + 6, Block.bookShelf.blockID);
            var1.setBlock(var3 + 5, var4 + 9, var5 + 7, Block.bookShelf.blockID);
            var1.setBlock(var3 + 5, var4 + 9, var5 + 8, Block.bookShelf.blockID);
            var1.setBlockAndMetadata(var3 + 5, var4 + 9, var5 + 9, RCBB.bookcasemeta.blockID, 1);
            var1.setBlockAndMetadata(var3 + 5, var4 + 9, var5 + 10, Block.wood.blockID, 1);
            var1.setBlock(var3 + 5, var4 + 9, var5 + 11, Block.cloth.blockID);
            var1.setBlock(var3 + 5, var4 + 9, var5 + 12, Block.thinGlass.blockID);
            var1.setBlock(var3 + 5, var4 + 9, var5 + 13, Block.cloth.blockID);
            var1.setBlockAndMetadata(var3 + 5, var4 + 9, var5 + 14, Block.wood.blockID, 1);
            var1.setBlockAndMetadata(var3 + 5, var4 + 9, var5 + 15, RCBB.bookcasemeta.blockID, 1);
            var1.setBlock(var3 + 5, var4 + 9, var5 + 16, Block.bookShelf.blockID);
            var1.setBlock(var3 + 5, var4 + 9, var5 + 17, Block.bookShelf.blockID);
            var1.setBlock(var3 + 5, var4 + 9, var5 + 18, Block.bookShelf.blockID);
            var1.setBlockAndMetadata(var3 + 5, var4 + 9, var5 + 19, Block.wood.blockID, 1);
            var1.setBlockAndMetadata(var3 + 5, var4 + 10, var5 + 3, Block.stoneSingleSlab.blockID, 2);
            var1.setBlockAndMetadata(var3 + 5, var4 + 10, var5 + 4, Block.stoneDoubleSlab.blockID, 2);
            var1.setBlockAndMetadata(var3 + 5, var4 + 10, var5 + 5, Block.wood.blockID, 1);
            var1.setBlock(var3 + 5, var4 + 10, var5 + 6, Block.bookShelf.blockID);
            var1.setBlock(var3 + 5, var4 + 10, var5 + 7, Block.bookShelf.blockID);
            var1.setBlock(var3 + 5, var4 + 10, var5 + 8, Block.bookShelf.blockID);
            var1.setBlock(var3 + 5, var4 + 10, var5 + 9, Block.bookShelf.blockID);
            var1.setBlockAndMetadata(var3 + 5, var4 + 10, var5 + 10, Block.wood.blockID, 1);
            var1.setBlock(var3 + 5, var4 + 10, var5 + 11, Block.cloth.blockID);
            var1.setBlock(var3 + 5, var4 + 10, var5 + 12, Block.cloth.blockID);
            var1.setBlock(var3 + 5, var4 + 10, var5 + 13, Block.cloth.blockID);
            var1.setBlockAndMetadata(var3 + 5, var4 + 10, var5 + 14, Block.wood.blockID, 1);
            var1.setBlock(var3 + 5, var4 + 10, var5 + 15, Block.bookShelf.blockID);
            var1.setBlock(var3 + 5, var4 + 10, var5 + 16, Block.bookShelf.blockID);
            var1.setBlock(var3 + 5, var4 + 10, var5 + 17, Block.bookShelf.blockID);
            var1.setBlock(var3 + 5, var4 + 10, var5 + 18, Block.bookShelf.blockID);
            var1.setBlockAndMetadata(var3 + 5, var4 + 10, var5 + 19, Block.wood.blockID, 1);
            var1.setBlockAndMetadata(var3 + 5, var4 + 10, var5 + 20, Block.stoneDoubleSlab.blockID, 2);
            var1.setBlockAndMetadata(var3 + 5, var4 + 10, var5 + 21, Block.stoneSingleSlab.blockID, 2);
            var1.setBlockAndMetadata(var3 + 5, var4 + 11, var5 + 5, Block.stoneSingleSlab.blockID, 2);
            var1.setBlockAndMetadata(var3 + 5, var4 + 11, var5 + 6, Block.stoneDoubleSlab.blockID, 2);
            var1.setBlock(var3 + 5, var4 + 11, var5 + 7, Block.planks.blockID);
            var1.setBlock(var3 + 5, var4 + 11, var5 + 8, Block.planks.blockID);
            var1.setBlock(var3 + 5, var4 + 11, var5 + 9, Block.planks.blockID);
            var1.setBlock(var3 + 5, var4 + 11, var5 + 10, Block.stairCompactPlanks.blockID);
            var1.setBlock(var3 + 5, var4 + 11, var5 + 11, Block.stairCompactPlanks.blockID);
            var1.setBlock(var3 + 5, var4 + 11, var5 + 12, Block.stairCompactPlanks.blockID);
            var1.setBlock(var3 + 5, var4 + 11, var5 + 13, Block.stairCompactPlanks.blockID);
            var1.setBlock(var3 + 5, var4 + 11, var5 + 14, Block.stairCompactPlanks.blockID);
            var1.setBlock(var3 + 5, var4 + 11, var5 + 15, Block.planks.blockID);
            var1.setBlock(var3 + 5, var4 + 11, var5 + 16, Block.planks.blockID);
            var1.setBlock(var3 + 5, var4 + 11, var5 + 17, Block.planks.blockID);
            var1.setBlock(var3 + 5, var4 + 11, var5 + 18, Block.planks.blockID);
            var1.setBlockAndMetadata(var3 + 5, var4 + 11, var5 + 19, Block.stoneSingleSlab.blockID, 2);
            var1.setBlock(var3 + 6, var4 + 0, var5 + 0, Block.grass.blockID);
            var1.setBlock(var3 + 6, var4 + 0, var5 + 1, Block.grass.blockID);
            var1.setBlock(var3 + 6, var4 + 0, var5 + 2, Block.grass.blockID);
            var1.setBlock(var3 + 6, var4 + 0, var5 + 3, Block.grass.blockID);
            var1.setBlock(var3 + 6, var4 + 0, var5 + 4, Block.dirt.blockID);
            var1.setBlock(var3 + 6, var4 + 0, var5 + 5, Block.dirt.blockID);
            var1.setBlock(var3 + 6, var4 + 0, var5 + 6, Block.grass.blockID);
            var1.setBlock(var3 + 6, var4 + 0, var5 + 7, Block.grass.blockID);
            var1.setBlock(var3 + 6, var4 + 0, var5 + 8, Block.grass.blockID);
            var1.setBlock(var3 + 6, var4 + 0, var5 + 9, Block.grass.blockID);
            var1.setBlock(var3 + 6, var4 + 0, var5 + 10, Block.grass.blockID);
            var1.setBlock(var3 + 6, var4 + 0, var5 + 11, Block.grass.blockID);
            var1.setBlock(var3 + 6, var4 + 0, var5 + 12, Block.grass.blockID);
            var1.setBlock(var3 + 6, var4 + 0, var5 + 13, Block.grass.blockID);
            var1.setBlock(var3 + 6, var4 + 0, var5 + 14, Block.grass.blockID);
            var1.setBlock(var3 + 6, var4 + 0, var5 + 15, Block.grass.blockID);
            var1.setBlock(var3 + 6, var4 + 0, var5 + 16, Block.grass.blockID);
            var1.setBlock(var3 + 6, var4 + 0, var5 + 17, Block.grass.blockID);
            var1.setBlock(var3 + 6, var4 + 0, var5 + 18, Block.grass.blockID);
            var1.setBlock(var3 + 6, var4 + 0, var5 + 19, Block.dirt.blockID);
            var1.setBlock(var3 + 6, var4 + 0, var5 + 20, Block.dirt.blockID);
            var1.setBlock(var3 + 6, var4 + 0, var5 + 21, Block.grass.blockID);
            var1.setBlock(var3 + 6, var4 + 0, var5 + 22, Block.grass.blockID);
            var1.setBlock(var3 + 6, var4 + 0, var5 + 23, Block.grass.blockID);
            var1.setBlock(var3 + 6, var4 + 0, var5 + 24, Block.grass.blockID);
            var1.setBlock(var3 + 6, var4 + 0, var5 + 25, Block.grass.blockID);
            var1.setBlock(var3 + 6, var4 + 0, var5 + 26, Block.grass.blockID);
            var1.setBlock(var3 + 6, var4 + 1, var5 + 4, Block.cobblestone.blockID);
            var1.setBlock(var3 + 6, var4 + 1, var5 + 5, Block.cobblestone.blockID);
            var1.setBlock(var3 + 6, var4 + 1, var5 + 19, Block.cobblestone.blockID);
            var1.setBlock(var3 + 6, var4 + 1, var5 + 20, Block.cobblestone.blockID);
            var1.setBlock(var3 + 6, var4 + 2, var5 + 5, Block.cobblestone.blockID);
            var1.setBlock(var3 + 6, var4 + 2, var5 + 19, Block.cobblestone.blockID);
            var1.setBlockAndMetadata(var3 + 6, var4 + 3, var5 + 4, Block.stoneSingleSlab.blockID, 3);
            var1.setBlockAndMetadata(var3 + 6, var4 + 3, var5 + 5, Block.wood.blockID, 1);
            var1.setBlockAndMetadata(var3 + 6, var4 + 3, var5 + 6, Block.planks.blockID, 2);
            var1.setBlockAndMetadata(var3 + 6, var4 + 3, var5 + 7, Block.planks.blockID, 2);
            var1.setBlockAndMetadata(var3 + 6, var4 + 3, var5 + 8, Block.planks.blockID, 2);
            var1.setBlockAndMetadata(var3 + 6, var4 + 3, var5 + 9, Block.planks.blockID, 2);
            var1.setBlockAndMetadata(var3 + 6, var4 + 3, var5 + 10, Block.planks.blockID, 2);
            var1.setBlockAndMetadata(var3 + 6, var4 + 3, var5 + 11, Block.planks.blockID, 2);
            var1.setBlockAndMetadata(var3 + 6, var4 + 3, var5 + 12, Block.planks.blockID, 2);
            var1.setBlockAndMetadata(var3 + 6, var4 + 3, var5 + 13, Block.planks.blockID, 2);
            var1.setBlockAndMetadata(var3 + 6, var4 + 3, var5 + 14, Block.planks.blockID, 2);
            var1.setBlockAndMetadata(var3 + 6, var4 + 3, var5 + 15, Block.planks.blockID, 2);
            var1.setBlockAndMetadata(var3 + 6, var4 + 3, var5 + 16, Block.planks.blockID, 2);
            var1.setBlockAndMetadata(var3 + 6, var4 + 3, var5 + 17, Block.planks.blockID, 2);
            var1.setBlockAndMetadata(var3 + 6, var4 + 3, var5 + 18, Block.planks.blockID, 2);
            var1.setBlockAndMetadata(var3 + 6, var4 + 3, var5 + 19, Block.wood.blockID, 1);
            var1.setBlockAndMetadata(var3 + 6, var4 + 3, var5 + 20, Block.stoneSingleSlab.blockID, 3);
            var1.setBlockAndMetadata(var3 + 6, var4 + 4, var5 + 5, Block.wood.blockID, 1);
            var1.setBlockAndMetadata(var3 + 6, var4 + 4, var5 + 6, Block.wood.blockID, 1);
            var1.setBlockAndMetadata(var3 + 6, var4 + 4, var5 + 7, Block.stairCompactPlanks.blockID, 1);
            var1.setBlockAndMetadata(var3 + 6, var4 + 4, var5 + 8, Block.stairCompactPlanks.blockID, 1);
            var1.setBlockAndMetadata(var3 + 6, var4 + 4, var5 + 9, Block.wood.blockID, 1);
            var1.setBlockAndMetadata(var3 + 6, var4 + 4, var5 + 10, Block.wood.blockID, 1);
            var1.setBlockAndMetadata(var3 + 6, var4 + 4, var5 + 11, Block.planks.blockID, 2);
            var1.setBlockAndMetadata(var3 + 6, var4 + 4, var5 + 13, Block.planks.blockID, 2);
            var1.setBlockAndMetadata(var3 + 6, var4 + 4, var5 + 14, Block.wood.blockID, 1);
            var1.setBlockAndMetadata(var3 + 6, var4 + 4, var5 + 19, Block.wood.blockID, 1);
            var1.setBlockAndMetadata(var3 + 6, var4 + 5, var5 + 5, Block.planks.blockID, 2);
            var1.setBlockAndMetadata(var3 + 6, var4 + 5, var5 + 10, Block.wood.blockID, 1);
            var1.setBlockAndMetadata(var3 + 6, var4 + 5, var5 + 11, Block.planks.blockID, 2);
            var1.setBlockAndMetadata(var3 + 6, var4 + 5, var5 + 13, Block.planks.blockID, 2);
            var1.setBlockAndMetadata(var3 + 6, var4 + 5, var5 + 14, Block.wood.blockID, 1);
            var1.setBlockAndMetadata(var3 + 6, var4 + 5, var5 + 19, Block.planks.blockID, 2);
            var1.setBlockAndMetadata(var3 + 6, var4 + 6, var5 + 4, Block.stairCompactCobblestone.blockID, 6);
            var1.setBlockAndMetadata(var3 + 6, var4 + 6, var5 + 5, Block.planks.blockID, 2);
            var1.setBlock(var3 + 6, var4 + 6, var5 + 6, Block.web.blockID);
            var1.setBlock(var3 + 6, var4 + 6, var5 + 9, Block.web.blockID);
            var1.setBlockAndMetadata(var3 + 6, var4 + 6, var5 + 10, Block.wood.blockID, 1);
            var1.setBlockAndMetadata(var3 + 6, var4 + 6, var5 + 11, Block.wood.blockID, 1);
            var1.setBlockAndMetadata(var3 + 6, var4 + 6, var5 + 12, Block.wood.blockID, 1);
            var1.setBlockAndMetadata(var3 + 6, var4 + 6, var5 + 13, Block.wood.blockID, 1);
            var1.setBlockAndMetadata(var3 + 6, var4 + 6, var5 + 14, Block.wood.blockID, 1);
            var1.setBlockAndMetadata(var3 + 6, var4 + 6, var5 + 19, Block.planks.blockID, 2);
            var1.setBlockAndMetadata(var3 + 6, var4 + 6, var5 + 20, Block.stoneSingleSlab.blockID, 10);
            var1.setBlockAndMetadata(var3 + 6, var4 + 7, var5 + 4, Block.wood.blockID, 1);
            var1.setBlockAndMetadata(var3 + 6, var4 + 7, var5 + 5, Block.planks.blockID, 2);
            var1.setBlockAndMetadata(var3 + 6, var4 + 7, var5 + 6, Block.planks.blockID, 2);
            var1.setBlockAndMetadata(var3 + 6, var4 + 7, var5 + 7, Block.planks.blockID, 2);
            var1.setBlockAndMetadata(var3 + 6, var4 + 7, var5 + 8, Block.planks.blockID, 2);
            var1.setBlockAndMetadata(var3 + 6, var4 + 7, var5 + 9, Block.planks.blockID, 2);
            var1.setBlockAndMetadata(var3 + 6, var4 + 7, var5 + 10, Block.planks.blockID, 2);
            var1.setBlockAndMetadata(var3 + 6, var4 + 7, var5 + 11, Block.planks.blockID, 2);
            var1.setBlockAndMetadata(var3 + 6, var4 + 7, var5 + 12, Block.planks.blockID, 2);
            var1.setBlockAndMetadata(var3 + 6, var4 + 7, var5 + 13, Block.planks.blockID, 2);
            var1.setBlockAndMetadata(var3 + 6, var4 + 7, var5 + 14, Block.planks.blockID, 2);
            var1.setBlockAndMetadata(var3 + 6, var4 + 7, var5 + 15, Block.planks.blockID, 2);
            var1.setBlockAndMetadata(var3 + 6, var4 + 7, var5 + 16, Block.planks.blockID, 2);
            var1.setBlockAndMetadata(var3 + 6, var4 + 7, var5 + 17, Block.planks.blockID, 2);
            var1.setBlockAndMetadata(var3 + 6, var4 + 7, var5 + 18, Block.planks.blockID, 2);
            var1.setBlockAndMetadata(var3 + 6, var4 + 7, var5 + 19, Block.planks.blockID, 2);
            var1.setBlockAndMetadata(var3 + 6, var4 + 7, var5 + 20, Block.wood.blockID, 1);
            var1.setBlockAndMetadata(var3 + 6, var4 + 8, var5 + 4, Block.wood.blockID, 1);
            var1.setBlockAndMetadata(var3 + 6, var4 + 8, var5 + 20, Block.wood.blockID, 1);
            var1.setBlockAndMetadata(var3 + 6, var4 + 9, var5 + 4, Block.wood.blockID, 1);
            var1.setBlockAndMetadata(var3 + 6, var4 + 9, var5 + 20, Block.wood.blockID, 1);
            var1.setBlockAndMetadata(var3 + 6, var4 + 10, var5 + 3, Block.stairCompactPlanks.blockID, 2);
            var1.setBlockAndMetadata(var3 + 6, var4 + 10, var5 + 4, Block.wood.blockID, 1);
            var1.setBlockAndMetadata(var3 + 6, var4 + 10, var5 + 20, Block.wood.blockID, 1);
            var1.setBlockAndMetadata(var3 + 6, var4 + 10, var5 + 21, Block.stairCompactPlanks.blockID, 3);
            var1.setBlockAndMetadata(var3 + 6, var4 + 11, var5 + 4, Block.stairCompactPlanks.blockID, 2);
            var1.setBlock(var3 + 6, var4 + 11, var5 + 5, Block.planks.blockID);
            var1.setBlock(var3 + 6, var4 + 11, var5 + 6, Block.planks.blockID);
            var1.setBlock(var3 + 6, var4 + 11, var5 + 7, Block.planks.blockID);
            var1.setBlock(var3 + 6, var4 + 11, var5 + 8, Block.planks.blockID);
            var1.setBlock(var3 + 6, var4 + 11, var5 + 9, Block.planks.blockID);
            var1.setBlock(var3 + 6, var4 + 11, var5 + 10, Block.planks.blockID);
            var1.setBlock(var3 + 6, var4 + 11, var5 + 11, Block.planks.blockID);
            var1.setBlock(var3 + 6, var4 + 11, var5 + 12, Block.planks.blockID);
            var1.setBlock(var3 + 6, var4 + 11, var5 + 13, Block.planks.blockID);
            var1.setBlock(var3 + 6, var4 + 11, var5 + 14, Block.planks.blockID);
            var1.setBlock(var3 + 6, var4 + 11, var5 + 15, Block.planks.blockID);
            var1.setBlock(var3 + 6, var4 + 11, var5 + 16, Block.planks.blockID);
            var1.setBlock(var3 + 6, var4 + 11, var5 + 17, Block.planks.blockID);
            var1.setBlock(var3 + 6, var4 + 11, var5 + 18, Block.planks.blockID);
            var1.setBlock(var3 + 6, var4 + 11, var5 + 19, Block.planks.blockID);
            var1.setBlockAndMetadata(var3 + 6, var4 + 11, var5 + 20, Block.stairCompactPlanks.blockID, 3);
            var1.setBlock(var3 + 7, var4 + 0, var5 + 0, Block.grass.blockID);
            var1.setBlock(var3 + 7, var4 + 0, var5 + 1, Block.grass.blockID);
            var1.setBlock(var3 + 7, var4 + 0, var5 + 2, Block.grass.blockID);
            var1.setBlock(var3 + 7, var4 + 0, var5 + 3, Block.grass.blockID);
            var1.setBlock(var3 + 7, var4 + 0, var5 + 4, Block.grass.blockID);
            var1.setBlock(var3 + 7, var4 + 0, var5 + 5, Block.dirt.blockID);
            var1.setBlock(var3 + 7, var4 + 0, var5 + 6, Block.grass.blockID);
            var1.setBlock(var3 + 7, var4 + 0, var5 + 7, Block.grass.blockID);
            var1.setBlock(var3 + 7, var4 + 0, var5 + 8, Block.grass.blockID);
            var1.setBlock(var3 + 7, var4 + 0, var5 + 9, Block.grass.blockID);
            var1.setBlock(var3 + 7, var4 + 0, var5 + 10, Block.grass.blockID);
            var1.setBlock(var3 + 7, var4 + 0, var5 + 11, Block.grass.blockID);
            var1.setBlock(var3 + 7, var4 + 0, var5 + 12, Block.grass.blockID);
            var1.setBlock(var3 + 7, var4 + 0, var5 + 13, Block.grass.blockID);
            var1.setBlock(var3 + 7, var4 + 0, var5 + 14, Block.grass.blockID);
            var1.setBlock(var3 + 7, var4 + 0, var5 + 15, Block.grass.blockID);
            var1.setBlock(var3 + 7, var4 + 0, var5 + 16, Block.grass.blockID);
            var1.setBlock(var3 + 7, var4 + 0, var5 + 17, Block.grass.blockID);
            var1.setBlock(var3 + 7, var4 + 0, var5 + 18, Block.grass.blockID);
            var1.setBlock(var3 + 7, var4 + 0, var5 + 19, Block.dirt.blockID);
            var1.setBlock(var3 + 7, var4 + 0, var5 + 20, Block.grass.blockID);
            var1.setBlock(var3 + 7, var4 + 0, var5 + 21, Block.grass.blockID);
            var1.setBlock(var3 + 7, var4 + 0, var5 + 22, Block.grass.blockID);
            var1.setBlock(var3 + 7, var4 + 0, var5 + 23, Block.grass.blockID);
            var1.setBlock(var3 + 7, var4 + 0, var5 + 24, Block.grass.blockID);
            var1.setBlock(var3 + 7, var4 + 0, var5 + 25, Block.grass.blockID);
            var1.setBlock(var3 + 7, var4 + 0, var5 + 26, Block.grass.blockID);
            var1.setBlockAndMetadata(var3 + 7, var4 + 1, var5 + 4, Block.stairCompactCobblestone.blockID, 2);
            var1.setBlock(var3 + 7, var4 + 1, var5 + 5, Block.cobblestone.blockID);
            var1.setBlock(var3 + 7, var4 + 1, var5 + 19, Block.cobblestone.blockID);
            var1.setBlockAndMetadata(var3 + 7, var4 + 1, var5 + 20, Block.stairCompactCobblestone.blockID, 3);
            var1.setBlock(var3 + 7, var4 + 2, var5 + 4, Block.cobblestone.blockID);
            var1.setBlock(var3 + 7, var4 + 2, var5 + 5, Block.cobblestone.blockID);
            var1.setBlock(var3 + 7, var4 + 2, var5 + 19, Block.cobblestone.blockID);
            var1.setBlock(var3 + 7, var4 + 2, var5 + 20, Block.cobblestone.blockID);
            var1.setBlockAndMetadata(var3 + 7, var4 + 3, var5 + 4, Block.stoneSingleSlab.blockID, 3);
            var1.setBlockAndMetadata(var3 + 7, var4 + 3, var5 + 5, Block.wood.blockID, 1);
            var1.setBlockAndMetadata(var3 + 7, var4 + 3, var5 + 6, Block.planks.blockID, 2);
            var1.setBlockAndMetadata(var3 + 7, var4 + 3, var5 + 7, Block.planks.blockID, 2);
            var1.setBlockAndMetadata(var3 + 7, var4 + 3, var5 + 8, Block.planks.blockID, 2);
            var1.setBlockAndMetadata(var3 + 7, var4 + 3, var5 + 9, Block.planks.blockID, 2);
            var1.setBlockAndMetadata(var3 + 7, var4 + 3, var5 + 10, Block.planks.blockID, 2);
            var1.setBlockAndMetadata(var3 + 7, var4 + 3, var5 + 11, Block.cloth.blockID, 13);
            var1.setBlockAndMetadata(var3 + 7, var4 + 3, var5 + 12, Block.cloth.blockID, 13);
            var1.setBlockAndMetadata(var3 + 7, var4 + 3, var5 + 13, Block.cloth.blockID, 13);
            var1.setBlockAndMetadata(var3 + 7, var4 + 3, var5 + 14, Block.planks.blockID, 2);
            var1.setBlockAndMetadata(var3 + 7, var4 + 3, var5 + 15, Block.planks.blockID, 2);
            var1.setBlockAndMetadata(var3 + 7, var4 + 3, var5 + 16, Block.planks.blockID, 2);
            var1.setBlockAndMetadata(var3 + 7, var4 + 3, var5 + 17, Block.planks.blockID, 2);
            var1.setBlockAndMetadata(var3 + 7, var4 + 3, var5 + 18, Block.planks.blockID, 2);
            var1.setBlockAndMetadata(var3 + 7, var4 + 3, var5 + 19, Block.wood.blockID, 1);
            var1.setBlockAndMetadata(var3 + 7, var4 + 3, var5 + 20, Block.stoneSingleSlab.blockID, 3);
            var1.setBlockAndMetadata(var3 + 7, var4 + 4, var5 + 5, Block.wood.blockID, 1);
            var1.setBlockAndMetadata(var3 + 7, var4 + 4, var5 + 6, Block.stairCompactPlanks.blockID, 3);
            var1.setBlockAndMetadata(var3 + 7, var4 + 4, var5 + 9, Block.stairCompactPlanks.blockID, 2);
            var1.setBlockAndMetadata(var3 + 7, var4 + 4, var5 + 10, Block.wood.blockID, 1);
            var1.setBlockAndMetadata(var3 + 7, var4 + 4, var5 + 14, Block.wood.blockID, 1);
            var1.setBlockAndMetadata(var3 + 7, var4 + 4, var5 + 19, Block.wood.blockID, 1);
            var1.setBlock(var3 + 7, var4 + 5, var5 + 5, Block.thinGlass.blockID);
            var1.setBlock(var3 + 7, var4 + 5, var5 + 19, Block.thinGlass.blockID);
            var1.setBlockAndMetadata(var3 + 7, var4 + 6, var5 + 4, Block.stoneSingleSlab.blockID, 10);
            var1.setBlock(var3 + 7, var4 + 6, var5 + 5, Block.thinGlass.blockID);
            var1.setBlock(var3 + 7, var4 + 6, var5 + 19, Block.thinGlass.blockID);
            var1.setBlockAndMetadata(var3 + 7, var4 + 6, var5 + 20, Block.stoneSingleSlab.blockID, 10);
            var1.setBlockAndMetadata(var3 + 7, var4 + 7, var5 + 4, Block.wood.blockID, 1);
            var1.setBlockAndMetadata(var3 + 7, var4 + 7, var5 + 5, Block.planks.blockID, 2);
            var1.setBlockAndMetadata(var3 + 7, var4 + 7, var5 + 6, Block.planks.blockID, 2);
            var1.setBlockAndMetadata(var3 + 7, var4 + 7, var5 + 7, Block.planks.blockID, 2);
            var1.setBlockAndMetadata(var3 + 7, var4 + 7, var5 + 8, Block.planks.blockID, 2);
            var1.setBlockAndMetadata(var3 + 7, var4 + 7, var5 + 9, Block.planks.blockID, 2);
            var1.setBlockAndMetadata(var3 + 7, var4 + 7, var5 + 10, Block.planks.blockID, 2);
            var1.setBlockAndMetadata(var3 + 7, var4 + 7, var5 + 11, Block.planks.blockID, 2);
            var1.setBlockAndMetadata(var3 + 7, var4 + 7, var5 + 12, Block.planks.blockID, 2);
            var1.setBlockAndMetadata(var3 + 7, var4 + 7, var5 + 13, Block.planks.blockID, 2);
            var1.setBlockAndMetadata(var3 + 7, var4 + 7, var5 + 14, Block.planks.blockID, 2);
            var1.setBlockAndMetadata(var3 + 7, var4 + 7, var5 + 15, Block.planks.blockID, 2);
            var1.setBlockAndMetadata(var3 + 7, var4 + 7, var5 + 16, Block.planks.blockID, 2);
            var1.setBlockAndMetadata(var3 + 7, var4 + 7, var5 + 17, Block.planks.blockID, 2);
            var1.setBlockAndMetadata(var3 + 7, var4 + 7, var5 + 18, Block.planks.blockID, 2);
            var1.setBlockAndMetadata(var3 + 7, var4 + 7, var5 + 19, Block.planks.blockID, 2);
            var1.setBlockAndMetadata(var3 + 7, var4 + 7, var5 + 20, Block.wood.blockID, 1);
            var1.setBlock(var3 + 7, var4 + 8, var5 + 4, Block.cloth.blockID);
            var1.setBlockAndMetadata(var3 + 7, var4 + 8, var5 + 12, Block.stairCompactPlanks.blockID, 1);
            var1.setBlock(var3 + 7, var4 + 8, var5 + 20, Block.cloth.blockID);
            var1.setBlock(var3 + 7, var4 + 9, var5 + 4, Block.cloth.blockID);
            var1.setBlock(var3 + 7, var4 + 9, var5 + 20, Block.cloth.blockID);
            var1.setBlockAndMetadata(var3 + 7, var4 + 10, var5 + 3, Block.stairCompactPlanks.blockID, 2);
            var1.setBlockAndMetadata(var3 + 7, var4 + 10, var5 + 4, Block.wood.blockID, 1);
            var1.setBlockAndMetadata(var3 + 7, var4 + 10, var5 + 20, Block.wood.blockID, 1);
            var1.setBlockAndMetadata(var3 + 7, var4 + 10, var5 + 21, Block.stairCompactPlanks.blockID, 3);
            var1.setBlockAndMetadata(var3 + 7, var4 + 11, var5 + 4, Block.stairCompactPlanks.blockID, 2);
            var1.setBlock(var3 + 7, var4 + 11, var5 + 5, Block.planks.blockID);
            var1.setBlock(var3 + 7, var4 + 11, var5 + 6, Block.planks.blockID);
            var1.setBlock(var3 + 7, var4 + 11, var5 + 7, Block.planks.blockID);
            var1.setBlock(var3 + 7, var4 + 11, var5 + 8, Block.planks.blockID);
            var1.setBlock(var3 + 7, var4 + 11, var5 + 9, Block.planks.blockID);
            var1.setBlock(var3 + 7, var4 + 11, var5 + 10, Block.planks.blockID);
            var1.setBlock(var3 + 7, var4 + 11, var5 + 11, Block.planks.blockID);
            var1.setBlock(var3 + 7, var4 + 11, var5 + 12, Block.planks.blockID);
            var1.setBlock(var3 + 7, var4 + 11, var5 + 13, Block.planks.blockID);
            var1.setBlock(var3 + 7, var4 + 11, var5 + 14, Block.planks.blockID);
            var1.setBlock(var3 + 7, var4 + 11, var5 + 15, Block.planks.blockID);
            var1.setBlock(var3 + 7, var4 + 11, var5 + 16, Block.planks.blockID);
            var1.setBlock(var3 + 7, var4 + 11, var5 + 17, Block.planks.blockID);
            var1.setBlock(var3 + 7, var4 + 11, var5 + 18, Block.planks.blockID);
            var1.setBlock(var3 + 7, var4 + 11, var5 + 19, Block.planks.blockID);
            var1.setBlockAndMetadata(var3 + 7, var4 + 11, var5 + 20, Block.stairCompactPlanks.blockID, 3);
            var1.setBlock(var3 + 8, var4 + 0, var5 + 0, Block.grass.blockID);
            var1.setBlock(var3 + 8, var4 + 0, var5 + 1, Block.grass.blockID);
            var1.setBlock(var3 + 8, var4 + 0, var5 + 2, Block.grass.blockID);
            var1.setBlock(var3 + 8, var4 + 0, var5 + 3, Block.grass.blockID);
            var1.setBlock(var3 + 8, var4 + 0, var5 + 4, Block.dirt.blockID);
            var1.setBlock(var3 + 8, var4 + 0, var5 + 5, Block.dirt.blockID);
            var1.setBlock(var3 + 8, var4 + 0, var5 + 6, Block.grass.blockID);
            var1.setBlock(var3 + 8, var4 + 0, var5 + 7, Block.grass.blockID);
            var1.setBlock(var3 + 8, var4 + 0, var5 + 8, Block.grass.blockID);
            var1.setBlock(var3 + 8, var4 + 0, var5 + 9, Block.grass.blockID);
            var1.setBlock(var3 + 8, var4 + 0, var5 + 10, Block.grass.blockID);
            var1.setBlock(var3 + 8, var4 + 0, var5 + 11, Block.grass.blockID);
            var1.setBlock(var3 + 8, var4 + 0, var5 + 12, Block.grass.blockID);
            var1.setBlock(var3 + 8, var4 + 0, var5 + 13, Block.grass.blockID);
            var1.setBlock(var3 + 8, var4 + 0, var5 + 14, Block.grass.blockID);
            var1.setBlock(var3 + 8, var4 + 0, var5 + 15, Block.grass.blockID);
            var1.setBlock(var3 + 8, var4 + 0, var5 + 16, Block.grass.blockID);
            var1.setBlock(var3 + 8, var4 + 0, var5 + 17, Block.grass.blockID);
            var1.setBlock(var3 + 8, var4 + 0, var5 + 18, Block.grass.blockID);
            var1.setBlock(var3 + 8, var4 + 0, var5 + 19, Block.dirt.blockID);
            var1.setBlock(var3 + 8, var4 + 0, var5 + 20, Block.dirt.blockID);
            var1.setBlock(var3 + 8, var4 + 0, var5 + 21, Block.grass.blockID);
            var1.setBlock(var3 + 8, var4 + 0, var5 + 22, Block.grass.blockID);
            var1.setBlock(var3 + 8, var4 + 0, var5 + 23, Block.grass.blockID);
            var1.setBlock(var3 + 8, var4 + 0, var5 + 24, Block.grass.blockID);
            var1.setBlock(var3 + 8, var4 + 0, var5 + 25, Block.grass.blockID);
            var1.setBlock(var3 + 8, var4 + 0, var5 + 26, Block.grass.blockID);
            var1.setBlock(var3 + 8, var4 + 1, var5 + 4, Block.cobblestone.blockID);
            var1.setBlock(var3 + 8, var4 + 1, var5 + 5, Block.cobblestone.blockID);
            var1.setBlock(var3 + 8, var4 + 1, var5 + 19, Block.cobblestone.blockID);
            var1.setBlock(var3 + 8, var4 + 1, var5 + 20, Block.cobblestone.blockID);
            var1.setBlock(var3 + 8, var4 + 2, var5 + 5, Block.cobblestone.blockID);
            var1.setBlock(var3 + 8, var4 + 2, var5 + 19, Block.cobblestone.blockID);
            var1.setBlockAndMetadata(var3 + 8, var4 + 3, var5 + 4, Block.stoneSingleSlab.blockID, 3);
            var1.setBlockAndMetadata(var3 + 8, var4 + 3, var5 + 5, Block.wood.blockID, 1);
            var1.setBlockAndMetadata(var3 + 8, var4 + 3, var5 + 6, Block.planks.blockID, 2);
            var1.setBlockAndMetadata(var3 + 8, var4 + 3, var5 + 7, Block.planks.blockID, 2);
            var1.setBlockAndMetadata(var3 + 8, var4 + 3, var5 + 8, Block.planks.blockID, 2);
            var1.setBlockAndMetadata(var3 + 8, var4 + 3, var5 + 9, Block.planks.blockID, 2);
            var1.setBlockAndMetadata(var3 + 8, var4 + 3, var5 + 10, Block.planks.blockID, 2);
            var1.setBlockAndMetadata(var3 + 8, var4 + 3, var5 + 11, Block.cloth.blockID, 13);
            var1.setBlockAndMetadata(var3 + 8, var4 + 3, var5 + 12, Block.cloth.blockID, 13);
            var1.setBlockAndMetadata(var3 + 8, var4 + 3, var5 + 13, Block.cloth.blockID, 13);
            var1.setBlockAndMetadata(var3 + 8, var4 + 3, var5 + 14, Block.planks.blockID, 2);
            var1.setBlockAndMetadata(var3 + 8, var4 + 3, var5 + 15, Block.planks.blockID, 2);
            var1.setBlockAndMetadata(var3 + 8, var4 + 3, var5 + 16, Block.planks.blockID, 2);
            var1.setBlockAndMetadata(var3 + 8, var4 + 3, var5 + 17, Block.planks.blockID, 2);
            var1.setBlockAndMetadata(var3 + 8, var4 + 3, var5 + 18, Block.planks.blockID, 2);
            var1.setBlockAndMetadata(var3 + 8, var4 + 3, var5 + 19, Block.wood.blockID, 1);
            var1.setBlockAndMetadata(var3 + 8, var4 + 3, var5 + 20, Block.stoneSingleSlab.blockID, 3);
            var1.setBlockAndMetadata(var3 + 8, var4 + 4, var5 + 5, Block.wood.blockID, 1);
            var1.setBlockAndMetadata(var3 + 8, var4 + 4, var5 + 14, Block.wood.blockID, 1);
            var1.setBlockAndMetadata(var3 + 8, var4 + 4, var5 + 15, Block.wood.blockID, 1);
            var1.setBlockAndMetadata(var3 + 8, var4 + 4, var5 + 16, Block.wood.blockID, 1);
            var1.setBlockAndMetadata(var3 + 8, var4 + 4, var5 + 17, Block.fenceGate.blockID, 3);
            var1.setBlockAndMetadata(var3 + 8, var4 + 4, var5 + 18, Block.wood.blockID, 1);
            var1.setBlockAndMetadata(var3 + 8, var4 + 4, var5 + 19, Block.wood.blockID, 1);
            var1.setBlock(var3 + 8, var4 + 5, var5 + 5, Block.thinGlass.blockID);
            var1.setBlock(var3 + 8, var4 + 5, var5 + 19, Block.thinGlass.blockID);
            var1.setBlockAndMetadata(var3 + 8, var4 + 6, var5 + 4, Block.stoneSingleSlab.blockID, 10);
            var1.setBlock(var3 + 8, var4 + 6, var5 + 5, Block.thinGlass.blockID);
            var1.setBlock(var3 + 8, var4 + 6, var5 + 19, Block.thinGlass.blockID);
            var1.setBlockAndMetadata(var3 + 8, var4 + 6, var5 + 20, Block.stoneSingleSlab.blockID, 10);
            var1.setBlockAndMetadata(var3 + 8, var4 + 7, var5 + 4, Block.wood.blockID, 1);
            var1.setBlockAndMetadata(var3 + 8, var4 + 7, var5 + 5, Block.planks.blockID, 2);
            var1.setBlockAndMetadata(var3 + 8, var4 + 7, var5 + 6, Block.planks.blockID, 2);
            var1.setBlockAndMetadata(var3 + 8, var4 + 7, var5 + 7, Block.planks.blockID, 2);
            var1.setBlockAndMetadata(var3 + 8, var4 + 7, var5 + 8, Block.planks.blockID, 2);
            var1.setBlockAndMetadata(var3 + 8, var4 + 7, var5 + 9, Block.planks.blockID, 2);
            var1.setBlockAndMetadata(var3 + 8, var4 + 7, var5 + 10, Block.planks.blockID, 2);
            var1.setBlockAndMetadata(var3 + 8, var4 + 7, var5 + 11, Block.planks.blockID, 2);
            var1.setBlockAndMetadata(var3 + 8, var4 + 7, var5 + 12, Block.planks.blockID, 2);
            var1.setBlockAndMetadata(var3 + 8, var4 + 7, var5 + 13, Block.planks.blockID, 2);
            var1.setBlockAndMetadata(var3 + 8, var4 + 7, var5 + 14, Block.planks.blockID, 2);
            var1.setBlockAndMetadata(var3 + 8, var4 + 7, var5 + 15, Block.planks.blockID, 2);
            var1.setBlockAndMetadata(var3 + 8, var4 + 7, var5 + 16, Block.planks.blockID, 2);
            var1.setBlockAndMetadata(var3 + 8, var4 + 7, var5 + 17, Block.planks.blockID, 2);
            var1.setBlockAndMetadata(var3 + 8, var4 + 7, var5 + 18, Block.planks.blockID, 2);
            var1.setBlockAndMetadata(var3 + 8, var4 + 7, var5 + 19, Block.planks.blockID, 2);
            var1.setBlockAndMetadata(var3 + 8, var4 + 7, var5 + 20, Block.wood.blockID, 1);
            var1.setBlock(var3 + 8, var4 + 8, var5 + 4, Block.cloth.blockID);
            var1.setBlock(var3 + 8, var4 + 8, var5 + 5, Block.bookShelf.blockID);
            var1.setBlock(var3 + 8, var4 + 8, var5 + 6, Block.bookShelf.blockID);
            var1.setBlock(var3 + 8, var4 + 8, var5 + 7, Block.bookShelf.blockID);
            var1.setBlock(var3 + 8, var4 + 8, var5 + 8, Block.bookShelf.blockID);
            var1.setBlock(var3 + 8, var4 + 8, var5 + 9, Block.bookShelf.blockID);
            var1.setBlockAndMetadata(var3 + 8, var4 + 8, var5 + 11, Block.stairCompactPlanks.blockID, 3);
            var1.setBlock(var3 + 8, var4 + 8, var5 + 12, Block.fence.blockID);
            var1.setBlockAndMetadata(var3 + 8, var4 + 8, var5 + 13, Block.stairCompactPlanks.blockID, 2);
            var1.setBlock(var3 + 8, var4 + 8, var5 + 15, Block.bookShelf.blockID);
            var1.setBlock(var3 + 8, var4 + 8, var5 + 16, Block.bookShelf.blockID);
            var1.setBlock(var3 + 8, var4 + 8, var5 + 17, Block.bookShelf.blockID);
            var1.setBlock(var3 + 8, var4 + 8, var5 + 18, Block.bookShelf.blockID);
            var1.setBlock(var3 + 8, var4 + 8, var5 + 20, Block.cloth.blockID);
            var1.setBlock(var3 + 8, var4 + 9, var5 + 4, Block.cloth.blockID);
            var1.setBlock(var3 + 8, var4 + 9, var5 + 5, Block.bookShelf.blockID);
            var1.setBlock(var3 + 8, var4 + 9, var5 + 6, Block.bookShelf.blockID);
            var1.setBlock(var3 + 8, var4 + 9, var5 + 7, RCBB.Bookcasechest.blockID);
            var1.setBlock(var3 + 8, var4 + 9, var5 + 8, RCBB.Bookcasechest.blockID);
            var1.setBlock(var3 + 8, var4 + 9, var5 + 9, Block.bookShelf.blockID);
            var1.setBlock(var3 + 8, var4 + 9, var5 + 15, Block.bookShelf.blockID);
            var1.setBlock(var3 + 8, var4 + 9, var5 + 16, RCBB.Bookcasechest.blockID);
            var1.setBlock(var3 + 8, var4 + 9, var5 + 17, RCBB.Bookcasechest.blockID);
            var1.setBlock(var3 + 8, var4 + 9, var5 + 18, Block.bookShelf.blockID);
            var1.setBlock(var3 + 8, var4 + 9, var5 + 20, Block.cloth.blockID);
            var1.setBlockAndMetadata(var3 + 8, var4 + 10, var5 + 3, Block.stairCompactPlanks.blockID, 2);
            var1.setBlockAndMetadata(var3 + 8, var4 + 10, var5 + 4, Block.wood.blockID, 1);
            var1.setBlock(var3 + 8, var4 + 10, var5 + 5, Block.fence.blockID);
            var1.setBlock(var3 + 8, var4 + 10, var5 + 6, Block.fence.blockID);
            var1.setBlock(var3 + 8, var4 + 10, var5 + 7, Block.fence.blockID);
            var1.setBlock(var3 + 8, var4 + 10, var5 + 8, Block.fence.blockID);
            var1.setBlock(var3 + 8, var4 + 10, var5 + 9, Block.fence.blockID);
            var1.setBlock(var3 + 8, var4 + 10, var5 + 15, Block.fence.blockID);
            var1.setBlock(var3 + 8, var4 + 10, var5 + 16, Block.fence.blockID);
            var1.setBlock(var3 + 8, var4 + 10, var5 + 17, Block.fence.blockID);
            var1.setBlock(var3 + 8, var4 + 10, var5 + 18, Block.fence.blockID);
            var1.setBlockAndMetadata(var3 + 8, var4 + 10, var5 + 20, Block.wood.blockID, 1);
            var1.setBlockAndMetadata(var3 + 8, var4 + 10, var5 + 21, Block.stairCompactPlanks.blockID, 3);
            var1.setBlockAndMetadata(var3 + 8, var4 + 11, var5 + 4, Block.stairCompactPlanks.blockID, 2);
            var1.setBlock(var3 + 8, var4 + 11, var5 + 5, Block.planks.blockID);
            var1.setBlock(var3 + 8, var4 + 11, var5 + 6, Block.planks.blockID);
            var1.setBlock(var3 + 8, var4 + 11, var5 + 7, Block.planks.blockID);
            var1.setBlock(var3 + 8, var4 + 11, var5 + 8, Block.planks.blockID);
            var1.setBlock(var3 + 8, var4 + 11, var5 + 9, Block.planks.blockID);
            var1.setBlock(var3 + 8, var4 + 11, var5 + 10, Block.planks.blockID);
            var1.setBlock(var3 + 8, var4 + 11, var5 + 11, Block.planks.blockID);
            var1.setBlock(var3 + 8, var4 + 11, var5 + 12, Block.planks.blockID);
            var1.setBlock(var3 + 8, var4 + 11, var5 + 13, Block.planks.blockID);
            var1.setBlock(var3 + 8, var4 + 11, var5 + 14, Block.planks.blockID);
            var1.setBlock(var3 + 8, var4 + 11, var5 + 15, Block.planks.blockID);
            var1.setBlock(var3 + 8, var4 + 11, var5 + 16, Block.planks.blockID);
            var1.setBlock(var3 + 8, var4 + 11, var5 + 17, Block.planks.blockID);
            var1.setBlock(var3 + 8, var4 + 11, var5 + 18, Block.planks.blockID);
            var1.setBlock(var3 + 8, var4 + 11, var5 + 19, Block.planks.blockID);
            var1.setBlockAndMetadata(var3 + 8, var4 + 11, var5 + 20, Block.stairCompactPlanks.blockID, 3);
            var1.setBlock(var3 + 9, var4 + 0, var5 + 0, Block.grass.blockID);
            var1.setBlock(var3 + 9, var4 + 0, var5 + 1, Block.grass.blockID);
            var1.setBlock(var3 + 9, var4 + 0, var5 + 2, Block.grass.blockID);
            var1.setBlock(var3 + 9, var4 + 0, var5 + 3, Block.grass.blockID);
            var1.setBlock(var3 + 9, var4 + 0, var5 + 4, Block.grass.blockID);
            var1.setBlock(var3 + 9, var4 + 0, var5 + 5, Block.dirt.blockID);
            var1.setBlock(var3 + 9, var4 + 0, var5 + 6, Block.grass.blockID);
            var1.setBlock(var3 + 9, var4 + 0, var5 + 7, Block.grass.blockID);
            var1.setBlock(var3 + 9, var4 + 0, var5 + 8, Block.grass.blockID);
            var1.setBlock(var3 + 9, var4 + 0, var5 + 9, Block.grass.blockID);
            var1.setBlock(var3 + 9, var4 + 0, var5 + 10, Block.grass.blockID);
            var1.setBlock(var3 + 9, var4 + 0, var5 + 11, Block.grass.blockID);
            var1.setBlock(var3 + 9, var4 + 0, var5 + 12, Block.grass.blockID);
            var1.setBlock(var3 + 9, var4 + 0, var5 + 13, Block.grass.blockID);
            var1.setBlock(var3 + 9, var4 + 0, var5 + 14, Block.grass.blockID);
            var1.setBlock(var3 + 9, var4 + 0, var5 + 15, Block.grass.blockID);
            var1.setBlock(var3 + 9, var4 + 0, var5 + 16, Block.grass.blockID);
            var1.setBlock(var3 + 9, var4 + 0, var5 + 17, Block.grass.blockID);
            var1.setBlock(var3 + 9, var4 + 0, var5 + 18, Block.grass.blockID);
            var1.setBlock(var3 + 9, var4 + 0, var5 + 19, Block.dirt.blockID);
            var1.setBlock(var3 + 9, var4 + 0, var5 + 20, Block.grass.blockID);
            var1.setBlock(var3 + 9, var4 + 0, var5 + 21, Block.grass.blockID);
            var1.setBlock(var3 + 9, var4 + 0, var5 + 22, Block.grass.blockID);
            var1.setBlock(var3 + 9, var4 + 0, var5 + 23, Block.grass.blockID);
            var1.setBlock(var3 + 9, var4 + 0, var5 + 24, Block.grass.blockID);
            var1.setBlock(var3 + 9, var4 + 0, var5 + 25, Block.grass.blockID);
            var1.setBlock(var3 + 9, var4 + 0, var5 + 26, Block.grass.blockID);
            var1.setBlockAndMetadata(var3 + 9, var4 + 1, var5 + 4, Block.stairCompactCobblestone.blockID, 2);
            var1.setBlock(var3 + 9, var4 + 1, var5 + 5, Block.cobblestone.blockID);
            var1.setBlock(var3 + 9, var4 + 1, var5 + 19, Block.cobblestone.blockID);
            var1.setBlockAndMetadata(var3 + 9, var4 + 1, var5 + 20, Block.stairCompactCobblestone.blockID, 3);
            var1.setBlock(var3 + 9, var4 + 2, var5 + 4, Block.cobblestone.blockID);
            var1.setBlock(var3 + 9, var4 + 2, var5 + 5, Block.cobblestone.blockID);
            var1.setBlock(var3 + 9, var4 + 2, var5 + 19, Block.cobblestone.blockID);
            var1.setBlock(var3 + 9, var4 + 2, var5 + 20, Block.cobblestone.blockID);
            var1.setBlockAndMetadata(var3 + 9, var4 + 3, var5 + 4, Block.stoneSingleSlab.blockID, 3);
            var1.setBlockAndMetadata(var3 + 9, var4 + 3, var5 + 5, Block.wood.blockID, 1);
            var1.setBlockAndMetadata(var3 + 9, var4 + 3, var5 + 6, Block.planks.blockID, 2);
            var1.setBlockAndMetadata(var3 + 9, var4 + 3, var5 + 7, Block.planks.blockID, 2);
            var1.setBlockAndMetadata(var3 + 9, var4 + 3, var5 + 8, Block.planks.blockID, 2);
            var1.setBlockAndMetadata(var3 + 9, var4 + 3, var5 + 9, Block.planks.blockID, 2);
            var1.setBlockAndMetadata(var3 + 9, var4 + 3, var5 + 10, Block.planks.blockID, 2);
            var1.setBlockAndMetadata(var3 + 9, var4 + 3, var5 + 11, Block.cloth.blockID, 13);
            var1.setBlockAndMetadata(var3 + 9, var4 + 3, var5 + 12, Block.cloth.blockID, 13);
            var1.setBlockAndMetadata(var3 + 9, var4 + 3, var5 + 13, Block.cloth.blockID, 13);
            var1.setBlockAndMetadata(var3 + 9, var4 + 3, var5 + 14, Block.planks.blockID, 2);
            var1.setBlockAndMetadata(var3 + 9, var4 + 3, var5 + 15, Block.planks.blockID, 2);
            var1.setBlockAndMetadata(var3 + 9, var4 + 3, var5 + 16, Block.planks.blockID, 2);
            var1.setBlockAndMetadata(var3 + 9, var4 + 3, var5 + 17, Block.planks.blockID, 2);
            var1.setBlockAndMetadata(var3 + 9, var4 + 3, var5 + 18, Block.planks.blockID, 2);
            var1.setBlockAndMetadata(var3 + 9, var4 + 3, var5 + 19, Block.wood.blockID, 1);
            var1.setBlockAndMetadata(var3 + 9, var4 + 3, var5 + 20, Block.stoneSingleSlab.blockID, 3);
            var1.setBlockAndMetadata(var3 + 9, var4 + 4, var5 + 5, Block.wood.blockID, 1);
            var1.setBlockAndMetadata(var3 + 9, var4 + 4, var5 + 19, Block.wood.blockID, 1);
            var1.setBlockAndMetadata(var3 + 9, var4 + 5, var5 + 5, Block.planks.blockID, 2);
            var1.setBlockAndMetadata(var3 + 9, var4 + 5, var5 + 19, Block.planks.blockID, 2);
            var1.setBlockAndMetadata(var3 + 9, var4 + 6, var5 + 4, Block.stoneSingleSlab.blockID, 10);
            var1.setBlockAndMetadata(var3 + 9, var4 + 6, var5 + 5, Block.planks.blockID, 2);
            var1.setBlockAndMetadata(var3 + 9, var4 + 6, var5 + 19, Block.planks.blockID, 2);
            var1.setBlockAndMetadata(var3 + 9, var4 + 6, var5 + 20, Block.stoneSingleSlab.blockID, 10);
            var1.setBlockAndMetadata(var3 + 9, var4 + 7, var5 + 4, Block.wood.blockID, 1);
            var1.setBlockAndMetadata(var3 + 9, var4 + 7, var5 + 5, Block.planks.blockID, 2);
            var1.setBlockAndMetadata(var3 + 9, var4 + 7, var5 + 6, Block.planks.blockID, 2);
            var1.setBlockAndMetadata(var3 + 9, var4 + 7, var5 + 7, Block.planks.blockID, 2);
            var1.setBlockAndMetadata(var3 + 9, var4 + 7, var5 + 8, Block.planks.blockID, 2);
            var1.setBlockAndMetadata(var3 + 9, var4 + 7, var5 + 9, Block.planks.blockID, 2);
            var1.setBlockAndMetadata(var3 + 9, var4 + 7, var5 + 10, Block.planks.blockID, 2);
            var1.setBlockAndMetadata(var3 + 9, var4 + 7, var5 + 11, Block.planks.blockID, 2);
            var1.setBlockAndMetadata(var3 + 9, var4 + 7, var5 + 12, Block.planks.blockID, 2);
            var1.setBlockAndMetadata(var3 + 9, var4 + 7, var5 + 13, Block.planks.blockID, 2);
            var1.setBlockAndMetadata(var3 + 9, var4 + 7, var5 + 14, Block.planks.blockID, 2);
            var1.setBlockAndMetadata(var3 + 9, var4 + 7, var5 + 15, Block.planks.blockID, 2);
            var1.setBlockAndMetadata(var3 + 9, var4 + 7, var5 + 16, Block.planks.blockID, 2);
            var1.setBlockAndMetadata(var3 + 9, var4 + 7, var5 + 17, Block.planks.blockID, 2);
            var1.setBlockAndMetadata(var3 + 9, var4 + 7, var5 + 18, Block.planks.blockID, 2);
            var1.setBlockAndMetadata(var3 + 9, var4 + 7, var5 + 19, Block.planks.blockID, 2);
            var1.setBlockAndMetadata(var3 + 9, var4 + 7, var5 + 20, Block.wood.blockID, 1);
            var1.setBlockAndMetadata(var3 + 9, var4 + 8, var5 + 4, Block.wood.blockID, 1);
            var1.setBlock(var3 + 9, var4 + 8, var5 + 12, Block.stairCompactPlanks.blockID);
            var1.setBlockAndMetadata(var3 + 9, var4 + 8, var5 + 20, Block.wood.blockID, 1);
            var1.setBlockAndMetadata(var3 + 9, var4 + 9, var5 + 4, Block.wood.blockID, 1);
            var1.setBlockAndMetadata(var3 + 9, var4 + 9, var5 + 20, Block.wood.blockID, 1);
            var1.setBlockAndMetadata(var3 + 9, var4 + 10, var5 + 3, Block.stairCompactPlanks.blockID, 2);
            var1.setBlockAndMetadata(var3 + 9, var4 + 10, var5 + 4, Block.wood.blockID, 1);
            var1.setBlock(var3 + 9, var4 + 10, var5 + 7, Block.web.blockID);
            var1.setBlock(var3 + 9, var4 + 10, var5 + 8, Block.web.blockID);
            var1.setBlock(var3 + 9, var4 + 10, var5 + 9, Block.web.blockID);
            var1.setBlock(var3 + 9, var4 + 10, var5 + 10, Block.web.blockID);
            var1.setBlockAndMetadata(var3 + 9, var4 + 10, var5 + 20, Block.wood.blockID, 1);
            var1.setBlockAndMetadata(var3 + 9, var4 + 10, var5 + 21, Block.stairCompactPlanks.blockID, 3);
            var1.setBlockAndMetadata(var3 + 9, var4 + 11, var5 + 4, Block.stairCompactPlanks.blockID, 2);
            var1.setBlock(var3 + 9, var4 + 11, var5 + 5, Block.planks.blockID);
            var1.setBlock(var3 + 9, var4 + 11, var5 + 6, Block.planks.blockID);
            var1.setBlock(var3 + 9, var4 + 11, var5 + 7, Block.planks.blockID);
            var1.setBlock(var3 + 9, var4 + 11, var5 + 8, Block.planks.blockID);
            var1.setBlock(var3 + 9, var4 + 11, var5 + 9, Block.planks.blockID);
            var1.setBlock(var3 + 9, var4 + 11, var5 + 10, Block.planks.blockID);
            var1.setBlock(var3 + 9, var4 + 11, var5 + 11, Block.planks.blockID);
            var1.setBlock(var3 + 9, var4 + 11, var5 + 12, Block.planks.blockID);
            var1.setBlock(var3 + 9, var4 + 11, var5 + 13, Block.planks.blockID);
            var1.setBlock(var3 + 9, var4 + 11, var5 + 14, Block.planks.blockID);
            var1.setBlock(var3 + 9, var4 + 11, var5 + 15, Block.planks.blockID);
            var1.setBlock(var3 + 9, var4 + 11, var5 + 16, Block.planks.blockID);
            var1.setBlock(var3 + 9, var4 + 11, var5 + 17, Block.planks.blockID);
            var1.setBlock(var3 + 9, var4 + 11, var5 + 18, Block.planks.blockID);
            var1.setBlock(var3 + 9, var4 + 11, var5 + 19, Block.planks.blockID);
            var1.setBlockAndMetadata(var3 + 9, var4 + 11, var5 + 20, Block.stairCompactPlanks.blockID, 3);
            var1.setBlock(var3 + 10, var4 + 0, var5 + 0, Block.grass.blockID);
            var1.setBlock(var3 + 10, var4 + 0, var5 + 1, Block.grass.blockID);
            var1.setBlock(var3 + 10, var4 + 0, var5 + 2, Block.grass.blockID);
            var1.setBlock(var3 + 10, var4 + 0, var5 + 3, Block.grass.blockID);
            var1.setBlock(var3 + 10, var4 + 0, var5 + 4, Block.dirt.blockID);
            var1.setBlock(var3 + 10, var4 + 0, var5 + 5, Block.dirt.blockID);
            var1.setBlock(var3 + 10, var4 + 0, var5 + 6, Block.grass.blockID);
            var1.setBlock(var3 + 10, var4 + 0, var5 + 7, Block.grass.blockID);
            var1.setBlock(var3 + 10, var4 + 0, var5 + 8, Block.grass.blockID);
            var1.setBlock(var3 + 10, var4 + 0, var5 + 9, Block.grass.blockID);
            var1.setBlock(var3 + 10, var4 + 0, var5 + 10, Block.grass.blockID);
            var1.setBlock(var3 + 10, var4 + 0, var5 + 11, Block.grass.blockID);
            var1.setBlock(var3 + 10, var4 + 0, var5 + 12, Block.grass.blockID);
            var1.setBlock(var3 + 10, var4 + 0, var5 + 13, Block.grass.blockID);
            var1.setBlock(var3 + 10, var4 + 0, var5 + 14, Block.grass.blockID);
            var1.setBlock(var3 + 10, var4 + 0, var5 + 15, Block.grass.blockID);
            var1.setBlock(var3 + 10, var4 + 0, var5 + 16, Block.grass.blockID);
            var1.setBlock(var3 + 10, var4 + 0, var5 + 17, Block.grass.blockID);
            var1.setBlock(var3 + 10, var4 + 0, var5 + 18, Block.grass.blockID);
            var1.setBlock(var3 + 10, var4 + 0, var5 + 19, Block.dirt.blockID);
            var1.setBlock(var3 + 10, var4 + 0, var5 + 20, Block.dirt.blockID);
            var1.setBlock(var3 + 10, var4 + 0, var5 + 21, Block.grass.blockID);
            var1.setBlock(var3 + 10, var4 + 0, var5 + 22, Block.grass.blockID);
            var1.setBlock(var3 + 10, var4 + 0, var5 + 23, Block.grass.blockID);
            var1.setBlock(var3 + 10, var4 + 0, var5 + 24, Block.grass.blockID);
            var1.setBlock(var3 + 10, var4 + 0, var5 + 25, Block.grass.blockID);
            var1.setBlock(var3 + 10, var4 + 0, var5 + 26, Block.grass.blockID);
            var1.setBlock(var3 + 10, var4 + 1, var5 + 4, Block.cobblestone.blockID);
            var1.setBlock(var3 + 10, var4 + 1, var5 + 5, Block.cobblestone.blockID);
            var1.setBlock(var3 + 10, var4 + 1, var5 + 19, Block.cobblestone.blockID);
            var1.setBlock(var3 + 10, var4 + 1, var5 + 20, Block.cobblestone.blockID);
            var1.setBlock(var3 + 10, var4 + 2, var5 + 5, Block.cobblestone.blockID);
            var1.setBlock(var3 + 10, var4 + 2, var5 + 19, Block.cobblestone.blockID);
            var1.setBlockAndMetadata(var3 + 10, var4 + 3, var5 + 4, Block.stoneSingleSlab.blockID, 3);
            var1.setBlockAndMetadata(var3 + 10, var4 + 3, var5 + 5, Block.wood.blockID, 1);
            var1.setBlockAndMetadata(var3 + 10, var4 + 3, var5 + 6, Block.planks.blockID, 2);
            var1.setBlockAndMetadata(var3 + 10, var4 + 3, var5 + 7, Block.planks.blockID, 2);
            var1.setBlockAndMetadata(var3 + 10, var4 + 3, var5 + 8, Block.planks.blockID, 2);
            var1.setBlockAndMetadata(var3 + 10, var4 + 3, var5 + 9, Block.planks.blockID, 2);
            var1.setBlock(var3 + 10, var4 + 3, var5 + 10, Block.glowStone.blockID);
            var1.setBlockAndMetadata(var3 + 10, var4 + 3, var5 + 11, Block.cloth.blockID, 13);
            var1.setBlockAndMetadata(var3 + 10, var4 + 3, var5 + 12, Block.cloth.blockID, 13);
            var1.setBlockAndMetadata(var3 + 10, var4 + 3, var5 + 13, Block.cloth.blockID, 13);
            var1.setBlock(var3 + 10, var4 + 3, var5 + 14, Block.glowStone.blockID);
            var1.setBlockAndMetadata(var3 + 10, var4 + 3, var5 + 15, Block.planks.blockID, 2);
            var1.setBlockAndMetadata(var3 + 10, var4 + 3, var5 + 16, Block.planks.blockID, 2);
            var1.setBlockAndMetadata(var3 + 10, var4 + 3, var5 + 17, Block.planks.blockID, 2);
            var1.setBlockAndMetadata(var3 + 10, var4 + 3, var5 + 18, Block.planks.blockID, 2);
            var1.setBlockAndMetadata(var3 + 10, var4 + 3, var5 + 19, Block.wood.blockID, 1);
            var1.setBlockAndMetadata(var3 + 10, var4 + 3, var5 + 20, Block.stoneSingleSlab.blockID, 3);
            var1.setBlockAndMetadata(var3 + 10, var4 + 4, var5 + 5, Block.wood.blockID, 1);
            var1.setBlock(var3 + 10, var4 + 4, var5 + 7, Block.bookShelf.blockID);
            var1.setBlock(var3 + 10, var4 + 4, var5 + 8, Block.bookShelf.blockID);
            var1.setBlock(var3 + 10, var4 + 4, var5 + 9, Block.bookShelf.blockID);
            var1.setBlock(var3 + 10, var4 + 4, var5 + 15, Block.bookShelf.blockID);
            var1.setBlock(var3 + 10, var4 + 4, var5 + 16, Block.bookShelf.blockID);
            var1.setBlock(var3 + 10, var4 + 4, var5 + 17, Block.bookShelf.blockID);
            var1.setBlockAndMetadata(var3 + 10, var4 + 4, var5 + 19, Block.wood.blockID, 1);
            var1.setBlockAndMetadata(var3 + 10, var4 + 5, var5 + 5, Block.wood.blockID, 1);
            var1.setBlock(var3 + 10, var4 + 5, var5 + 7, Block.bookShelf.blockID);
            var1.setBlock(var3 + 10, var4 + 5, var5 + 8, RCBB.bookcasemeta.blockID);
            var1.setBlock(var3 + 10, var4 + 5, var5 + 9, Block.bookShelf.blockID);
            var1.setBlock(var3 + 10, var4 + 5, var5 + 15, Block.bookShelf.blockID);
            var1.setBlock(var3 + 10, var4 + 5, var5 + 16, Block.bookShelf.blockID);
            var1.setBlock(var3 + 10, var4 + 5, var5 + 17, Block.bookShelf.blockID);
            var1.setBlockAndMetadata(var3 + 10, var4 + 5, var5 + 19, Block.wood.blockID, 1);
            var1.setBlockAndMetadata(var3 + 10, var4 + 6, var5 + 4, Block.stoneSingleSlab.blockID, 10);
            var1.setBlockAndMetadata(var3 + 10, var4 + 6, var5 + 5, Block.wood.blockID, 1);
            var1.setBlock(var3 + 10, var4 + 6, var5 + 7, Block.bookShelf.blockID);
            var1.setBlock(var3 + 10, var4 + 6, var5 + 8, Block.bookShelf.blockID);
            var1.setBlock(var3 + 10, var4 + 6, var5 + 9, Block.bookShelf.blockID);
            var1.setBlock(var3 + 10, var4 + 6, var5 + 15, Block.bookShelf.blockID);
            var1.setBlock(var3 + 10, var4 + 6, var5 + 16, Block.bookShelf.blockID);
            var1.setBlock(var3 + 10, var4 + 6, var5 + 17, Block.bookShelf.blockID);
            var1.setBlockAndMetadata(var3 + 10, var4 + 6, var5 + 19, Block.wood.blockID, 1);
            var1.setBlockAndMetadata(var3 + 10, var4 + 6, var5 + 20, Block.stoneSingleSlab.blockID, 10);
            var1.setBlockAndMetadata(var3 + 10, var4 + 7, var5 + 4, Block.wood.blockID, 1);
            var1.setBlockAndMetadata(var3 + 10, var4 + 7, var5 + 5, Block.planks.blockID, 2);
            var1.setBlockAndMetadata(var3 + 10, var4 + 7, var5 + 6, Block.planks.blockID, 2);
            var1.setBlockAndMetadata(var3 + 10, var4 + 7, var5 + 7, Block.planks.blockID, 2);
            var1.setBlockAndMetadata(var3 + 10, var4 + 7, var5 + 8, Block.planks.blockID, 2);
            var1.setBlockAndMetadata(var3 + 10, var4 + 7, var5 + 9, Block.planks.blockID, 2);
            var1.setBlockAndMetadata(var3 + 10, var4 + 7, var5 + 10, Block.planks.blockID, 2);
            var1.setBlockAndMetadata(var3 + 10, var4 + 7, var5 + 11, Block.planks.blockID, 2);
            var1.setBlockAndMetadata(var3 + 10, var4 + 7, var5 + 12, Block.planks.blockID, 2);
            var1.setBlockAndMetadata(var3 + 10, var4 + 7, var5 + 13, Block.planks.blockID, 2);
            var1.setBlockAndMetadata(var3 + 10, var4 + 7, var5 + 14, Block.planks.blockID, 2);
            var1.setBlockAndMetadata(var3 + 10, var4 + 7, var5 + 15, Block.planks.blockID, 2);
            var1.setBlockAndMetadata(var3 + 10, var4 + 7, var5 + 16, Block.planks.blockID, 2);
            var1.setBlockAndMetadata(var3 + 10, var4 + 7, var5 + 17, Block.planks.blockID, 2);
            var1.setBlockAndMetadata(var3 + 10, var4 + 7, var5 + 18, Block.planks.blockID, 2);
            var1.setBlockAndMetadata(var3 + 10, var4 + 7, var5 + 19, Block.planks.blockID, 2);
            var1.setBlockAndMetadata(var3 + 10, var4 + 7, var5 + 20, Block.wood.blockID, 1);
            var1.setBlock(var3 + 10, var4 + 8, var5 + 4, Block.cloth.blockID);
            var1.setBlock(var3 + 10, var4 + 8, var5 + 20, Block.cloth.blockID);
            var1.setBlock(var3 + 10, var4 + 9, var5 + 4, Block.cloth.blockID);
            var1.setBlock(var3 + 10, var4 + 9, var5 + 20, Block.cloth.blockID);
            var1.setBlockAndMetadata(var3 + 10, var4 + 10, var5 + 3, Block.stairCompactPlanks.blockID, 2);
            var1.setBlockAndMetadata(var3 + 10, var4 + 10, var5 + 4, Block.wood.blockID, 1);
            var1.setBlock(var3 + 10, var4 + 10, var5 + 5, Block.web.blockID);
            var1.setBlock(var3 + 10, var4 + 10, var5 + 6, Block.web.blockID);
            var1.setBlock(var3 + 10, var4 + 10, var5 + 7, Block.web.blockID);
            var1.setBlockAndMetadata(var3 + 10, var4 + 10, var5 + 20, Block.wood.blockID, 1);
            var1.setBlockAndMetadata(var3 + 10, var4 + 10, var5 + 21, Block.stairCompactPlanks.blockID, 3);
            var1.setBlockAndMetadata(var3 + 10, var4 + 11, var5 + 4, Block.stairCompactPlanks.blockID, 2);
            var1.setBlock(var3 + 10, var4 + 11, var5 + 5, Block.planks.blockID);
            var1.setBlock(var3 + 10, var4 + 11, var5 + 6, Block.planks.blockID);
            var1.setBlock(var3 + 10, var4 + 11, var5 + 7, Block.planks.blockID);
            var1.setBlock(var3 + 10, var4 + 11, var5 + 8, Block.planks.blockID);
            var1.setBlock(var3 + 10, var4 + 11, var5 + 9, Block.planks.blockID);
            var1.setBlock(var3 + 10, var4 + 11, var5 + 10, Block.planks.blockID);
            var1.setBlock(var3 + 10, var4 + 11, var5 + 11, Block.planks.blockID);
            var1.setBlock(var3 + 10, var4 + 11, var5 + 12, Block.planks.blockID);
            var1.setBlock(var3 + 10, var4 + 11, var5 + 13, Block.planks.blockID);
            var1.setBlock(var3 + 10, var4 + 11, var5 + 14, Block.planks.blockID);
            var1.setBlock(var3 + 10, var4 + 11, var5 + 15, Block.planks.blockID);
            var1.setBlock(var3 + 10, var4 + 11, var5 + 16, Block.planks.blockID);
            var1.setBlock(var3 + 10, var4 + 11, var5 + 17, Block.planks.blockID);
            var1.setBlock(var3 + 10, var4 + 11, var5 + 18, Block.planks.blockID);
            var1.setBlock(var3 + 10, var4 + 11, var5 + 19, Block.planks.blockID);
            var1.setBlockAndMetadata(var3 + 10, var4 + 11, var5 + 20, Block.stairCompactPlanks.blockID, 3);
            var1.setBlock(var3 + 11, var4 + 0, var5 + 0, Block.grass.blockID);
            var1.setBlock(var3 + 11, var4 + 0, var5 + 1, Block.grass.blockID);
            var1.setBlock(var3 + 11, var4 + 0, var5 + 2, Block.grass.blockID);
            var1.setBlock(var3 + 11, var4 + 0, var5 + 3, Block.grass.blockID);
            var1.setBlock(var3 + 11, var4 + 0, var5 + 4, Block.grass.blockID);
            var1.setBlock(var3 + 11, var4 + 0, var5 + 5, Block.dirt.blockID);
            var1.setBlock(var3 + 11, var4 + 0, var5 + 6, Block.grass.blockID);
            var1.setBlock(var3 + 11, var4 + 0, var5 + 7, Block.grass.blockID);
            var1.setBlock(var3 + 11, var4 + 0, var5 + 8, Block.grass.blockID);
            var1.setBlock(var3 + 11, var4 + 0, var5 + 9, Block.grass.blockID);
            var1.setBlock(var3 + 11, var4 + 0, var5 + 10, Block.grass.blockID);
            var1.setBlock(var3 + 11, var4 + 0, var5 + 11, Block.grass.blockID);
            var1.setBlock(var3 + 11, var4 + 0, var5 + 12, Block.grass.blockID);
            var1.setBlock(var3 + 11, var4 + 0, var5 + 13, Block.grass.blockID);
            var1.setBlock(var3 + 11, var4 + 0, var5 + 14, Block.grass.blockID);
            var1.setBlock(var3 + 11, var4 + 0, var5 + 15, Block.grass.blockID);
            var1.setBlock(var3 + 11, var4 + 0, var5 + 16, Block.grass.blockID);
            var1.setBlock(var3 + 11, var4 + 0, var5 + 17, Block.grass.blockID);
            var1.setBlock(var3 + 11, var4 + 0, var5 + 18, Block.grass.blockID);
            var1.setBlock(var3 + 11, var4 + 0, var5 + 19, Block.dirt.blockID);
            var1.setBlock(var3 + 11, var4 + 0, var5 + 20, Block.grass.blockID);
            var1.setBlock(var3 + 11, var4 + 0, var5 + 21, Block.grass.blockID);
            var1.setBlock(var3 + 11, var4 + 0, var5 + 22, Block.grass.blockID);
            var1.setBlock(var3 + 11, var4 + 0, var5 + 23, Block.grass.blockID);
            var1.setBlock(var3 + 11, var4 + 0, var5 + 24, Block.grass.blockID);
            var1.setBlock(var3 + 11, var4 + 0, var5 + 25, Block.grass.blockID);
            var1.setBlock(var3 + 11, var4 + 0, var5 + 26, Block.grass.blockID);
            var1.setBlockAndMetadata(var3 + 11, var4 + 1, var5 + 4, Block.stairCompactCobblestone.blockID, 2);
            var1.setBlock(var3 + 11, var4 + 1, var5 + 5, Block.cobblestone.blockID);
            var1.setBlock(var3 + 11, var4 + 1, var5 + 19, Block.cobblestone.blockID);
            var1.setBlockAndMetadata(var3 + 11, var4 + 1, var5 + 20, Block.stairCompactCobblestone.blockID, 3);
            var1.setBlock(var3 + 11, var4 + 2, var5 + 4, Block.cobblestone.blockID);
            var1.setBlock(var3 + 11, var4 + 2, var5 + 5, Block.cobblestone.blockID);
            var1.setBlock(var3 + 11, var4 + 2, var5 + 19, Block.cobblestone.blockID);
            var1.setBlock(var3 + 11, var4 + 2, var5 + 20, Block.cobblestone.blockID);
            var1.setBlockAndMetadata(var3 + 11, var4 + 3, var5 + 4, Block.stoneSingleSlab.blockID, 3);
            var1.setBlockAndMetadata(var3 + 11, var4 + 3, var5 + 5, Block.wood.blockID, 1);
            var1.setBlockAndMetadata(var3 + 11, var4 + 3, var5 + 6, Block.planks.blockID, 2);
            var1.setBlockAndMetadata(var3 + 11, var4 + 3, var5 + 7, Block.planks.blockID, 2);
            var1.setBlockAndMetadata(var3 + 11, var4 + 3, var5 + 8, Block.planks.blockID, 2);
            var1.setBlockAndMetadata(var3 + 11, var4 + 3, var5 + 9, Block.planks.blockID, 2);
            var1.setBlockAndMetadata(var3 + 11, var4 + 3, var5 + 10, Block.planks.blockID, 2);
            var1.setBlockAndMetadata(var3 + 11, var4 + 3, var5 + 11, Block.cloth.blockID, 13);
            var1.setBlockAndMetadata(var3 + 11, var4 + 3, var5 + 12, Block.cloth.blockID, 13);
            var1.setBlockAndMetadata(var3 + 11, var4 + 3, var5 + 13, Block.cloth.blockID, 13);
            var1.setBlockAndMetadata(var3 + 11, var4 + 3, var5 + 14, Block.planks.blockID, 2);
            var1.setBlockAndMetadata(var3 + 11, var4 + 3, var5 + 15, Block.planks.blockID, 2);
            var1.setBlockAndMetadata(var3 + 11, var4 + 3, var5 + 16, Block.planks.blockID, 2);
            var1.setBlockAndMetadata(var3 + 11, var4 + 3, var5 + 17, Block.planks.blockID, 2);
            var1.setBlockAndMetadata(var3 + 11, var4 + 3, var5 + 18, Block.planks.blockID, 2);
            var1.setBlockAndMetadata(var3 + 11, var4 + 3, var5 + 19, Block.wood.blockID, 1);
            var1.setBlockAndMetadata(var3 + 11, var4 + 3, var5 + 20, Block.stoneSingleSlab.blockID, 3);
            var1.setBlockAndMetadata(var3 + 11, var4 + 4, var5 + 5, Block.wood.blockID, 1);
            var1.setBlockAndMetadata(var3 + 11, var4 + 4, var5 + 19, Block.wood.blockID, 1);
            var1.setBlockAndMetadata(var3 + 11, var4 + 5, var5 + 5, Block.planks.blockID, 2);
            var1.setBlockAndMetadata(var3 + 11, var4 + 5, var5 + 19, Block.planks.blockID, 2);
            var1.setBlockAndMetadata(var3 + 11, var4 + 6, var5 + 4, Block.stoneSingleSlab.blockID, 10);
            var1.setBlockAndMetadata(var3 + 11, var4 + 6, var5 + 5, Block.planks.blockID, 2);
            var1.setBlock(var3 + 11, var4 + 6, var5 + 6, Block.web.blockID);
            var1.setBlock(var3 + 11, var4 + 6, var5 + 7, Block.web.blockID);
            var1.setBlock(var3 + 11, var4 + 6, var5 + 8, Block.web.blockID);
            var1.setBlock(var3 + 11, var4 + 6, var5 + 9, Block.web.blockID);
            var1.setBlock(var3 + 11, var4 + 6, var5 + 10, Block.web.blockID);
            var1.setBlock(var3 + 11, var4 + 6, var5 + 11, Block.web.blockID);
            var1.setBlock(var3 + 11, var4 + 6, var5 + 14, Block.web.blockID);
            var1.setBlock(var3 + 11, var4 + 6, var5 + 15, Block.web.blockID);
            var1.setBlock(var3 + 11, var4 + 6, var5 + 16, Block.web.blockID);
            var1.setBlock(var3 + 11, var4 + 6, var5 + 17, Block.web.blockID);
            var1.setBlock(var3 + 11, var4 + 6, var5 + 18, Block.web.blockID);
            var1.setBlockAndMetadata(var3 + 11, var4 + 6, var5 + 19, Block.planks.blockID, 2);
            var1.setBlockAndMetadata(var3 + 11, var4 + 6, var5 + 20, Block.stoneSingleSlab.blockID, 10);
            var1.setBlockAndMetadata(var3 + 11, var4 + 7, var5 + 4, Block.wood.blockID, 1);
            var1.setBlockAndMetadata(var3 + 11, var4 + 7, var5 + 5, Block.planks.blockID, 2);
            var1.setBlockAndMetadata(var3 + 11, var4 + 7, var5 + 6, Block.planks.blockID, 2);
            var1.setBlockAndMetadata(var3 + 11, var4 + 7, var5 + 7, Block.planks.blockID, 2);
            var1.setBlockAndMetadata(var3 + 11, var4 + 7, var5 + 8, Block.planks.blockID, 2);
            var1.setBlockAndMetadata(var3 + 11, var4 + 7, var5 + 9, Block.planks.blockID, 2);
            var1.setBlockAndMetadata(var3 + 11, var4 + 7, var5 + 10, Block.planks.blockID, 2);
            var1.setBlockAndMetadata(var3 + 11, var4 + 7, var5 + 11, Block.planks.blockID, 2);
            var1.setBlockAndMetadata(var3 + 11, var4 + 7, var5 + 12, Block.planks.blockID, 2);
